Workbook

Sheet 每日推薦
A1: 每日10檔推薦清單
A2: 日期： | B2: 46142 | D2: 資料來源： | E2: 2026/04/30 市場新聞、外資報告整理
A3: 免責聲明：本表僅供參考，非投資建議。實際投資請自行研究並承擔風險。
A5: 排名 | B5: 股票代號 | C5: 股票名稱 | D5: 所屬類股 | E5: 推薦理由/題材 | F5: 备註
A6: 1 | B6: 2330 | C6: 台積電 | D6: 半導體/晶圓代工 | E6: 外資 AI 共識首選,2nm 量產推進、定價穩定;高盛、瑞銀、摩根士丹利一致按讚 | F6: 未追蹤
A7: 2 | B7: 2317 | C7: 鴻海 | D7: EMS/AI 伺服器 | E7: AI 伺服器組裝龍頭,外資 2026 共識買進名單 | F7: 未追蹤
A8: 3 | B8: 3443 | C8: 創意 | D8: ASIC 設計 | E8: ASIC 動能強勁,外資 2026 共識買進、營收持續創高 | F8: 未追蹤
A9: 4 | B9: 2308 | C9: 台達電 | D9: AI 伺服器電源/散熱 | E9: AI 伺服器電源龍頭,HVDC 800V 架構領先,2026~2027 加速成長 | F9: 未追蹤
A10: 5 | B10: 2383 | C10: 台光電 | D10: CCL/AI 材料 | E10: CCL 絕對核心領導股,M8/M9 技術領先,2026 下半年 M9 量產 | F10: 未追蹤
A11: 6 | B11: 3017 | C11: 奇鋐 | D11: 散熱模組 | E11: AI 伺服器散熱模組龍頭,液冷需求強勁 | F11: 未追蹤
A12: 7 | B12: 2344 | C12: 華邦電 | D12: 記憶體 | E12: DDR5 第四季漲 53~58%,記憶體領頭羊,點燃 AI 與矽光子題材 | F12: 未追蹤
A13: 8 | B13: 2408 | C13: 南亞科 | D13: 記憶體 | E13: DDR5 受惠 SK 海力士、美光轉產 HBM 後產能轉移 | F13: 未追蹤
A14: 9 | B14: 8996 | C14: 高力 | D14: 電源/燃料電池 | E14: AI 資料中心電力供應鏈、燃料電池受惠美國電網建置加速 | F14: 未追蹤
A15: 10 | B15: 2454 | C15: 聯發科 | D15: IC 設計 | E15: ASIC 動能強勁,盤中漲勢領軍 | F15: 未追蹤
A17: 追蹤個股燈號同步
A18: 資料同步自各個股分頁（以最新收盤 = 第 25 列）；燈號、評註、買賣參考價均為公式連動。
A20: 代號 | B20: 名稱 | C20: 收盤 | D20: 總燈號 | E20: 評註（通過/警示/危險） | F20: 買進/賣出參考價位
A21: 2324 | B21: 仁寶 | C21: ='2324 仁寶'!E25 -> 29 | D21: ='2324 仁寶'!S15 -> 🔴 觀望 | E21: ='2324 仁寶'!R15 -> 通過 2 / 7 警示 1 危險 3 | F21: ="買進參考 "&TEXT('2324 仁寶'!R27,"0.0")&" / 賣出參考 "&TEXT('2324 仁寶'!R28,"0.0") -> 買進參考 28.2 / 賣出參考 29.8
A22: 2352 | B22: 佳世達 | C22: ='2352 佳世達'!E25 -> 23.9 | D22: ='2352 佳世達'!S15 -> 🔴 出場 | E22: ='2352 佳世達'!R15 -> 通過 2 / 7 警示 0 危險 4 | F22: ="買進參考 "&TEXT('2352 佳世達'!R27,"0.0")&" / 賣出參考 "&TEXT('2352 佳世達'!R28,"0.0") -> 買進參考 23.5 / 賣出參考 24.3
A23: 2376 | B23: 技嘉 | C23: ='2376 技嘉'!E25 -> 273 | D23: ='2376 技嘉'!S15 -> 🔴 觀望 | E23: ='2376 技嘉'!R15 -> 通過 2 / 7 警示 1 危險 3 | F23: ="買進參考 "&TEXT('2376 技嘉'!R27,"0.0")&" / 賣出參考 "&TEXT('2376 技嘉'!R28,"0.0") -> 買進參考 263.9 / 賣出參考 282.1
A24: 2379 | B24: 瑞昱 | C24: ='2379 瑞昱'!E25 -> 537 | D24: ='2379 瑞昱'!S15 -> 🔴 觀望 | E24: ='2379 瑞昱'!R15 -> 通過 2 / 7 警示 2 危險 2 | F24: ="買進參考 "&TEXT('2379 瑞昱'!R27,"0.0")&" / 賣出參考 "&TEXT('2379 瑞昱'!R28,"0.0") -> 買進參考 525.6 / 賣出參考 548.6
A25: 2382 | B25: 廣達 | C25: ='2382 廣達'!E25 -> 312.5 | D25: ='2382 廣達'!S15 -> 🔴 觀望 | E25: ='2382 廣達'!R15 -> 通過 2 / 7 警示 2 危險 2 | F25: ="買進參考 "&TEXT('2382 廣達'!R27,"0.0")&" / 賣出參考 "&TEXT('2382 廣達'!R28,"0.0") -> 買進參考 304.0 / 賣出參考 321.0
A26: 2395 | B26: 研華 | C26: ='2395 研華'!E25 -> 359.5 | D26: ='2395 研華'!S15 -> 🟡 等待 | E26: ='2395 研華'!R15 -> 通過 3 / 7 警示 2 危險 1 | F26: ="買進參考 "&TEXT('2395 研華'!R27,"0.0")&" / 賣出參考 "&TEXT('2395 研華'!R28,"0.0") -> 買進參考 351.1 / 賣出參考 367.9
A27: 3034 | B27: 聯詠 | C27: ='3034 聯詠'!E25 -> 409 | D27: ='3034 聯詠'!S15 -> 🔴 觀望 | E27: ='3034 聯詠'!R15 -> 通過 3 / 7 警示 0 危險 3 | F27: ="買進參考 "&TEXT('3034 聯詠'!R27,"0.0")&" / 賣出參考 "&TEXT('3034 聯詠'!R28,"0.0") -> 買進參考 400.0 / 賣出參考 418.0
A28: 3231 | B28: 緯創 | C28: ='3231 緯創'!E25 -> 137 | D28: ='3231 緯創'!S15 -> 🔴 觀望 | E28: ='3231 緯創'!R15 -> 通過 2 / 7 警示 1 危險 3 | F28: ="買進參考 "&TEXT('3231 緯創'!R27,"0.0")&" / 賣出參考 "&TEXT('3231 緯創'!R28,"0.0") -> 買進參考 133.9 / 賣出參考 140.4
A29: 5388 | B29: 中磊 | C29: ='5388 中磊'!E25 -> 76.5 | D29: ='5388 中磊'!S15 -> 🔴 出場 | E29: ='5388 中磊'!R15 -> 通過 1 / 7 警示 1 危險 4 | F29: ="買進參考 "&TEXT('5388 中磊'!R27,"0.0")&" / 賣出參考 "&TEXT('5388 中磊'!R28,"0.0") -> 買進參考 74.6 / 賣出參考 78.4
A30: 6285 | B30: 啟碚 | C30: ='6285 啟碁'!E25 -> 216 | D30: ='6285 啟碁'!S15 -> 🟡 等待 | E30: ='6285 啟碁'!R15 -> 通過 3 / 7 警示 2 危險 1 | F30: ="買進參考 "&TEXT('6285 啟碁'!R27,"0.0")&" / 賣出參考 "&TEXT('6285 啟碁'!R28,"0.0") -> 買進參考 202.4 / 賣出參考 229.6
A31: 2308 | B31: 台達電 | C31: ='2308 台達電'!E25 -> 2165 | D31: ='2308 台達電'!S15 -> 🟡 等待 | E31: ='2308 台達電'!R15 -> 通過 3 / 7 警示 3 危險 0 | F31: ="買進參考 "&TEXT('2308 台達電'!R27,"0.0")&" / 賣出參考 "&TEXT('2308 台達電'!R28,"0.0") -> 買進參考 2089.8 / 賣出參考 2240.2
A32: 2330 | B32: 台積電 | C32: ='2330 台積電'!E25 -> 2135 | D32: ='2330 台積電'!S15 -> 🟡 等待 | E32: ='2330 台積電'!R15 -> 通過 3 / 7 警示 2 危險 1 | F32: ="買進參考 "&TEXT('2330 台積電'!R27,"0.0")&" / 賣出參考 "&TEXT('2330 台積電'!R28,"0.0") -> 買進參考 2083.5 / 賣出參考 2196.0
A33: 2881 | B33: 富邦金 | C33: ='2881 富邦金'!E25 -> 90 | D33: ='2881 富邦金'!S15 -> 🟢 次強進場 | E33: ='2881 富邦金'!R15 -> 通過 5 / 7 警示 1 危險 0 | F33: ="買進參考 "&TEXT('2881 富邦金'!R27,"0.0")&" / 賣出參考 "&TEXT('2881 富邦金'!R28,"0.0") -> 買進參考 89.0 / 賣出參考 91.0
A34: 燈號記錄
A35: 🟢 進場 (強) | B35: 🟢 進場 (次強) | C35: 🟡 等待 | D35: 🔴 觀望 | E35: 🔴 出場 | F35: ⚪ 資料不足
A38: 4/30 賣 | B38: 2352 | C38: 佳世達 | D38: 23.9
A39: 4/30 賣 | B39: 5388 | C39: 中磊 | D39: 76.5
A43: python3 fetch_twse_daily.py -s 2324 2382 2395 3231 2379 5388 6285 2352 2376 3034 2330 2308 -n 20 -o stock.xlsx

Sheet 2324 仁寶
A1: 2324 仁寶 - 近20日股價追蹤
A2: 所屬產業： | B2: 筆電/伺服器
A3: 資料來源： | B3: 2324
A5: 日期 | B5: 大盤 | C5: 最高 | D5: 最低 | E5: 收盤 | F5: 成交量(張) | G5: 漲跌幅 | H5: MA5 | I5: MA10 | J5: MA20 | K5: RSI(6) | L5: RSI(12) | M5: KD-K | N5: KD-D | O5: MACD-OSC | Q5: 燈號儀表板
A6: {=INDIRECT("'"&$B$3&"'!"&CHAR(64+COLUMN())&(ROW()-4))} -> 46113 | B6: {=INDIRECT("'"&$B$3&"'!"&CHAR(64+COLUMN())&(ROW()-4))} -> 33174.82 | C6: {=INDIRECT("'"&$B$3&"'!"&CHAR(64+COLUMN())&(ROW()-4))} -> 27.7 | D6: {=INDIRECT("'"&$B$3&"'!"&CHAR(64+COLUMN())&(ROW()-4))} -> 26.95 | E6: {=INDIRECT("'"&$B$3&"'!"&CHAR(64+COLUMN())&(ROW()-4))} -> 27.45 | F6: {=INDIRECT("'"&$B$3&"'!"&CHAR(64+COLUMN())&(ROW()-4))} -> 34084 | G6: {=INDIRECT("'"&$B$3&"'!"&CHAR(64+COLUMN())&(ROW()-4))} -> 1.8552876 | H6: {=INDIRECT("'"&$B$3&"'!"&CHAR(64+COLUMN())&(ROW()-4))} -> 28.88 | ... O6: {=INDIRECT("'"&$B$3&"'!"&CHAR(64+COLUMN())&(ROW()-4))} -> -0.59574372 | Q6: 步驟 | R6: 條件 | S6: 燈號 | T6: 細節
A7: {=INDIRECT("'"&$B$3&"'!"&CHAR(64+COLUMN())&(ROW()-4))} -> 46114 | B7: {=INDIRECT("'"&$B$3&"'!"&CHAR(64+COLUMN())&(ROW()-4))} -> 32572.43 | C7: {=INDIRECT("'"&$B$3&"'!"&CHAR(64+COLUMN())&(ROW()-4))} -> 27.75 | D7: {=INDIRECT("'"&$B$3&"'!"&CHAR(64+COLUMN())&(ROW()-4))} -> 27 | E7: {=INDIRECT("'"&$B$3&"'!"&CHAR(64+COLUMN())&(ROW()-4))} -> 27.4 | F7: {=INDIRECT("'"&$B$3&"'!"&CHAR(64+COLUMN())&(ROW()-4))} -> 20383 | G7: {=INDIRECT("'"&$B$3&"'!"&CHAR(64+COLUMN())&(ROW()-4))} -> -0.18214936 | H7: {=INDIRECT("'"&$B$3&"'!"&CHAR(64+COLUMN())&(ROW()-4))} -> 28.06 | ... O7: {=INDIRECT("'"&$B$3&"'!"&CHAR(64+COLUMN())&(ROW()-4))} -> -0.60163435 | Q7: 1 | R7: 大盤過濾（大盤 > 自身 MA20） | S7: =IF(COUNT(B6:B25)<5,"⚪",IF(AND(B25>AVERAGE(B6:B25),B25>B20),"🟢",IF(OR(B25>AVERAGE(B6:B25),B25>B20),"🟡","🔴"))) -> 🟢 | T7: =IF(COUNT(B6:B25)<5,"大盤資料不足","大盤="&TEXT(B25,"#,##0")&" vs MA="&TEXT(AVERAGE(B6:B25),"#,##0")&" 斜率:"&IF(B25>B20,"↑","↓")) -> 大盤=38,927 vs MA=36,644 斜率:↑
A8: {=INDIRECT("'"&$B$3&"'!"&CHAR(64+COLUMN())&(ROW()-4))} -> 46119 | B8: {=INDIRECT("'"&$B$3&"'!"&CHAR(64+COLUMN())&(ROW()-4))} -> 33229.82 | C8: {=INDIRECT("'"&$B$3&"'!"&CHAR(64+COLUMN())&(ROW()-4))} -> 27.3 | D8: {=INDIRECT("'"&$B$3&"'!"&CHAR(64+COLUMN())&(ROW()-4))} -> 26.85 | E8: {=INDIRECT("'"&$B$3&"'!"&CHAR(64+COLUMN())&(ROW()-4))} -> 26.85 | F8: {=INDIRECT("'"&$B$3&"'!"&CHAR(64+COLUMN())&(ROW()-4))} -> 19351 | G8: {=INDIRECT("'"&$B$3&"'!"&CHAR(64+COLUMN())&(ROW()-4))} -> -2.0072993 | H8: {=INDIRECT("'"&$B$3&"'!"&CHAR(64+COLUMN())&(ROW()-4))} -> 27.38 | ... O8: {=INDIRECT("'"&$B$3&"'!"&CHAR(64+COLUMN())&(ROW()-4))} -> -0.60626194 | Q8: 2 | R8: 趨勢結構（MA10>MA20 且 MA20 斜率向上） | S8: =IF(OR(I25="",J25="",J20=""),"⚪",IF(AND(I25>J25,J25>J20),"🟢",IF(OR(I25>J25,J25>J20),"🟡","🔴"))) -> 🟢 | T8: =IF(OR(I25="",J25="",J20=""),"資料不足","MA10=" &TEXT(I25,"0.0")& " MA20=" &TEXT(J25,"0.0")& " " &IF(I25>J25,"多頭","空頭")& " 斜率:" &IF(J25>J20,"↑","↓")) -> MA10=30.5 MA20=29.4 多頭 斜率:↑
A9: {=INDIRECT("'"&$B$3&"'!"&CHAR(64+COLUMN())&(ROW()-4))} -> 46120 | B9: {=INDIRECT("'"&$B$3&"'!"&CHAR(64+COLUMN())&(ROW()-4))} -> 34761.38 | C9: {=INDIRECT("'"&$B$3&"'!"&CHAR(64+COLUMN())&(ROW()-4))} -> 27.9 | D9: {=INDIRECT("'"&$B$3&"'!"&CHAR(64+COLUMN())&(ROW()-4))} -> 26.75 | E9: {=INDIRECT("'"&$B$3&"'!"&CHAR(64+COLUMN())&(ROW()-4))} -> 27.9 | F9: {=INDIRECT("'"&$B$3&"'!"&CHAR(64+COLUMN())&(ROW()-4))} -> 32325 | G9: {=INDIRECT("'"&$B$3&"'!"&CHAR(64+COLUMN())&(ROW()-4))} -> 3.9106145 | H9: {=INDIRECT("'"&$B$3&"'!"&CHAR(64+COLUMN())&(ROW()-4))} -> 27.31 | ... O9: {=INDIRECT("'"&$B$3&"'!"&CHAR(64+COLUMN())&(ROW()-4))} -> -0.50636525 | Q9: 3 | R9: 動能三合（MA5>MA10 + KD金叉 + RSI6>50） | S9: =IF(OR(H25="",I25="",K25="",M25="",N25="",K24="",M24="",N24=""),"⚪",IF(AND(H25>I25,M25>N25,K25>50,OR(AND(M24<N24,M25>N25,M24<50),AND(K24<50,K25>=50),AND(M24<50,M25>=50))),"🟢",IF(AND(H25>I25,M25>N25,K25>50),"🟡",IF(SUM(IF(H25>I25,1,0),IF(M25>N25,1,0),IF(K25>50,1,0))>=2,"🟡","🔴")))) -> 🔴 | T9: ="MA金叉:"&IF(H25>I25,"✓","✗")&" KD金叉:"&IF(AND(M24<N24,M25>N25),"✓","✗")&"(K="&TEXT(M25,"0")&") RSI6:"&TEXT(K25,"0")&IF(AND(K24<50,K25>=50),"(首破50)","") -> MA金叉:✗ KD金叉:✗(K=18) RSI6:34
A10: {=INDIRECT("'"&$B$3&"'!"&CHAR(64+COLUMN())&(ROW()-4))} -> 46121 | B10: {=INDIRECT("'"&$B$3&"'!"&CHAR(64+COLUMN())&(ROW()-4))} -> 34861.16 | C10: {=INDIRECT("'"&$B$3&"'!"&CHAR(64+COLUMN())&(ROW()-4))} -> 27.75 | D10: {=INDIRECT("'"&$B$3&"'!"&CHAR(64+COLUMN())&(ROW()-4))} -> 27 | E10: {=INDIRECT("'"&$B$3&"'!"&CHAR(64+COLUMN())&(ROW()-4))} -> 27.3 | F10: {=INDIRECT("'"&$B$3&"'!"&CHAR(64+COLUMN())&(ROW()-4))} -> 28992 | G10: {=INDIRECT("'"&$B$3&"'!"&CHAR(64+COLUMN())&(ROW()-4))} -> -2.1505376 | H10: {=INDIRECT("'"&$B$3&"'!"&CHAR(64+COLUMN())&(ROW()-4))} -> 27.38 | ... O10: {=INDIRECT("'"&$B$3&"'!"&CHAR(64+COLUMN())&(ROW()-4))} -> -0.45033655 | Q10: 4 | R10: 量能（≥1.5×5日均量） | S10: =IF(F25="","⚪",IF(S9="🟢",IF(F25>=1.5*AVERAGE(F20:F24),"🟢",IF(F25>=AVERAGE(F20:F24),"🟡","🔴")),IF(S12="🟢",IF(AND(E25>E24,F25<F24),"🔴",IF(F25>=AVERAGE(F20:F24),"🟢","🟡")),IF(F25>=1.5*AVERAGE(F20:F24),"🟢",IF(F25>=AVERAGE(F20:F24),"🟡","🔴"))))) -> 🔴 | T10: ="今量="&TEXT(F25,"#,##0")&" 5日均="&TEXT(AVERAGE(F20:F24),"#,##0")&" 比值="&TEXT(F25/AVERAGE(F20:F24),"0.00")&"x"&IF(AND(E25>E24,F25<F24)," ⚠價漲量縮","") -> 今量=24,600 5日均=44,278 比值=0.56x
A11: {=INDIRECT("'"&$B$3&"'!"&CHAR(64+COLUMN())&(ROW()-4))} -> 46122 | B11: {=INDIRECT("'"&$B$3&"'!"&CHAR(64+COLUMN())&(ROW()-4))} -> 35417.83 | C11: {=INDIRECT("'"&$B$3&"'!"&CHAR(64+COLUMN())&(ROW()-4))} -> 28.65 | D11: {=INDIRECT("'"&$B$3&"'!"&CHAR(64+COLUMN())&(ROW()-4))} -> 27.9 | E11: {=INDIRECT("'"&$B$3&"'!"&CHAR(64+COLUMN())&(ROW()-4))} -> 28.2 | F11: {=INDIRECT("'"&$B$3&"'!"&CHAR(64+COLUMN())&(ROW()-4))} -> 36016 | G11: {=INDIRECT("'"&$B$3&"'!"&CHAR(64+COLUMN())&(ROW()-4))} -> 3.2967033 | H11: {=INDIRECT("'"&$B$3&"'!"&CHAR(64+COLUMN())&(ROW()-4))} -> 27.53 | ... O11: {=INDIRECT("'"&$B$3&"'!"&CHAR(64+COLUMN())&(ROW()-4))} -> -0.32798767 | Q11: 5 | R11: 停損參考（三段） | S11: — | T11: ="緊 MA10=" & TEXT(I25,"0.0") & " 中 -" & TEXT(IF(N32<0.025,5,IF(N32<0.04,6,8)),"0") & "%=" & TEXT(E25*(1-IF(N32<0.025,0.05,IF(N32<0.04,0.06,0.08))),"0.0") & " 鬆 MA20=" & TEXT(J25,"0.0") & " (σ=" & TEXT(N32,"0.0%") & ")" -> 緊 MA10=30.5 中 -6%=27.3 鬆 MA20=29.4 (σ=2.6%)
A12: {=INDIRECT("'"&$B$3&"'!"&CHAR(64+COLUMN())&(ROW()-4))} -> 46125 | B12: {=INDIRECT("'"&$B$3&"'!"&CHAR(64+COLUMN())&(ROW()-4))} -> 35457.29 | C12: {=INDIRECT("'"&$B$3&"'!"&CHAR(64+COLUMN())&(ROW()-4))} -> 29.1 | D12: {=INDIRECT("'"&$B$3&"'!"&CHAR(64+COLUMN())&(ROW()-4))} -> 27.7 | E12: {=INDIRECT("'"&$B$3&"'!"&CHAR(64+COLUMN())&(ROW()-4))} -> 29 | F12: {=INDIRECT("'"&$B$3&"'!"&CHAR(64+COLUMN())&(ROW()-4))} -> 27744 | G12: {=INDIRECT("'"&$B$3&"'!"&CHAR(64+COLUMN())&(ROW()-4))} -> 2.8368794 | H12: {=INDIRECT("'"&$B$3&"'!"&CHAR(64+COLUMN())&(ROW()-4))} -> 27.85 | ... O12: {=INDIRECT("'"&$B$3&"'!"&CHAR(64+COLUMN())&(ROW()-4))} -> -0.17611853 | Q12: 6 | R12: 持有訊號（收盤>MA5） | S12: =IF(OR(E25="",H25=""),"⚪",IF(E25>H25,"🟢",IF(AND(E25<H25,E24<H24),"🔴","🟡"))) -> 🔴 | T12: ="收盤="&TEXT(E25,"0.0")&" MA5="&TEXT(H25,"0.0")&IF(E25>H25," 守穩",IF(AND(E25<H25,E24<H24)," 連2日跌破"," 單日跌破(警示)")) -> 收盤=29.0 MA5=29.8 連2日跌破
A13: {=INDIRECT("'"&$B$3&"'!"&CHAR(64+COLUMN())&(ROW()-4))} -> 46126 | B13: {=INDIRECT("'"&$B$3&"'!"&CHAR(64+COLUMN())&(ROW()-4))} -> 36296.12 | C13: {=INDIRECT("'"&$B$3&"'!"&CHAR(64+COLUMN())&(ROW()-4))} -> 29.75 | D13: {=INDIRECT("'"&$B$3&"'!"&CHAR(64+COLUMN())&(ROW()-4))} -> 29.1 | E13: {=INDIRECT("'"&$B$3&"'!"&CHAR(64+COLUMN())&(ROW()-4))} -> 29.5 | F13: {=INDIRECT("'"&$B$3&"'!"&CHAR(64+COLUMN())&(ROW()-4))} -> 35883 | G13: {=INDIRECT("'"&$B$3&"'!"&CHAR(64+COLUMN())&(ROW()-4))} -> 1.7241379 | H13: {=INDIRECT("'"&$B$3&"'!"&CHAR(64+COLUMN())&(ROW()-4))} -> 28.38 | ... O13: {=INDIRECT("'"&$B$3&"'!"&CHAR(64+COLUMN())&(ROW()-4))} -> -0.032451788 | Q13: 7 | R13: 出場警示（4取2） | S13: =IF(SUM(IF(AND(E25>MAX(E15:E24),K25<MAX(K15:K24)),1,0),IF(AND(E25>MAX(E15:E24),F25<MAX(F15:F24)),1,0),IF(AND(E25<H25,H25<H24),1,0),IF(AND(M24>N24,M25<N25,M24>80),1,0),IF(AND(E25<J25,E24<J24),1,0))>=2,"🔴",IF(SUM(IF(AND(E25>MAX(E15:E24),K25<MAX(K15:K24)),1,0),IF(AND(E25>MAX(E15:E24),F25<MAX(F15:F24)),1,0),IF(AND(E25<H25,H25<H24),1,0),IF(AND(M24>N24,M25<N25,M24>80),1,0),IF(AND(E25<J25,E24<J24),1,0))=1,"🟡","🟢")) -> 🟡 | T13: ="RSI背離:"&IF(AND(E25>MAX(E15:E24),K25<MAX(K15:K24)),"✓","✗")&" 量價背離:"&IF(AND(E25>MAX(E15:E24),F25<MAX(F15:F24)),"✓","✗")&" MA5翻下:"&IF(AND(E25<H25,H25<H24),"✓","✗")&" KD高死叉:"&IF(AND(M24>N24,M25<N25,M24>80),"✓","✗")&" 破MA20:"&IF(AND(E25<J25,E24<J24),"✓","✗") -> RSI背離:✗ 量價背離:✗ MA5翻下:✓ KD高死叉:✗ 破MA20:✗
A14: {=INDIRECT("'"&$B$3&"'!"&CHAR(64+COLUMN())&(ROW()-4))} -> 46127 | B14: {=INDIRECT("'"&$B$3&"'!"&CHAR(64+COLUMN())&(ROW()-4))} -> 36722.14 | C14: {=INDIRECT("'"&$B$3&"'!"&CHAR(64+COLUMN())&(ROW()-4))} -> 29.95 | D14: {=INDIRECT("'"&$B$3&"'!"&CHAR(64+COLUMN())&(ROW()-4))} -> 29.05 | E14: {=INDIRECT("'"&$B$3&"'!"&CHAR(64+COLUMN())&(ROW()-4))} -> 29.45 | F14: {=INDIRECT("'"&$B$3&"'!"&CHAR(64+COLUMN())&(ROW()-4))} -> 33328 | G14: {=INDIRECT("'"&$B$3&"'!"&CHAR(64+COLUMN())&(ROW()-4))} -> -0.16949153 | H14: {=INDIRECT("'"&$B$3&"'!"&CHAR(64+COLUMN())&(ROW()-4))} -> 28.69 | ... O14: {=INDIRECT("'"&$B$3&"'!"&CHAR(64+COLUMN())&(ROW()-4))} -> 0.063516855
A15: {=INDIRECT("'"&$B$3&"'!"&CHAR(64+COLUMN())&(ROW()-4))} -> 46128 | B15: {=INDIRECT("'"&$B$3&"'!"&CHAR(64+COLUMN())&(ROW()-4))} -> 37132.02 | C15: {=INDIRECT("'"&$B$3&"'!"&CHAR(64+COLUMN())&(ROW()-4))} -> 30.7 | D15: {=INDIRECT("'"&$B$3&"'!"&CHAR(64+COLUMN())&(ROW()-4))} -> 29.2 | E15: {=INDIRECT("'"&$B$3&"'!"&CHAR(64+COLUMN())&(ROW()-4))} -> 29.4 | F15: {=INDIRECT("'"&$B$3&"'!"&CHAR(64+COLUMN())&(ROW()-4))} -> 66959 | G15: {=INDIRECT("'"&$B$3&"'!"&CHAR(64+COLUMN())&(ROW()-4))} -> -0.16977929 | H15: {=INDIRECT("'"&$B$3&"'!"&CHAR(64+COLUMN())&(ROW()-4))} -> 29.11 | ... O15: {=INDIRECT("'"&$B$3&"'!"&CHAR(64+COLUMN())&(ROW()-4))} -> 0.12441365 | Q15: 總燈號 | R15: ="通過 "&(COUNTIF(S7:S13,"🟢"))&" / 7 警示 "&COUNTIF(S7:S13,"🟡")&" 危險 "&COUNTIF(S7:S13,"🔴") -> 通過 2 / 7 警示 1 危險 3 | S15: =IF(AND(S7="🟢",COUNTIF(S7:S10,"🟢")=4,S13<>"🔴"),"🟢 強進場",IF(AND(S7="🟢",COUNTIF(S7:S10,"🟢")>=3,S13<>"🔴"),"🟢 次強進場",IF(S13="🔴","🔴 出場",IF(COUNTIF(S7:S13,"🔴")>=2,"🔴 觀望","🟡 等待")))) -> 🔴 觀望 | T15: ="基於 "&TEXT(A25,"yyyy/mm/dd")&" 收盤資料" -> 基於 2026/04/30 收盤資料
A16: {=INDIRECT("'"&$B$3&"'!"&CHAR(64+COLUMN())&(ROW()-4))} -> 46129 | B16: {=INDIRECT("'"&$B$3&"'!"&CHAR(64+COLUMN())&(ROW()-4))} -> 36804.34 | C16: {=INDIRECT("'"&$B$3&"'!"&CHAR(64+COLUMN())&(ROW()-4))} -> 31.8 | D16: {=INDIRECT("'"&$B$3&"'!"&CHAR(64+COLUMN())&(ROW()-4))} -> 29.6 | E16: {=INDIRECT("'"&$B$3&"'!"&CHAR(64+COLUMN())&(ROW()-4))} -> 30.35 | F16: {=INDIRECT("'"&$B$3&"'!"&CHAR(64+COLUMN())&(ROW()-4))} -> 99623 | G16: {=INDIRECT("'"&$B$3&"'!"&CHAR(64+COLUMN())&(ROW()-4))} -> 3.2312925 | H16: {=INDIRECT("'"&$B$3&"'!"&CHAR(64+COLUMN())&(ROW()-4))} -> 29.54 | ... O16: {=INDIRECT("'"&$B$3&"'!"&CHAR(64+COLUMN())&(ROW()-4))} -> 0.22366988
A17: {=INDIRECT("'"&$B$3&"'!"&CHAR(64+COLUMN())&(ROW()-4))} -> 46132 | B17: {=INDIRECT("'"&$B$3&"'!"&CHAR(64+COLUMN())&(ROW()-4))} -> 36958.8 | C17: {=INDIRECT("'"&$B$3&"'!"&CHAR(64+COLUMN())&(ROW()-4))} -> 31.35 | D17: {=INDIRECT("'"&$B$3&"'!"&CHAR(64+COLUMN())&(ROW()-4))} -> 29.75 | E17: {=INDIRECT("'"&$B$3&"'!"&CHAR(64+COLUMN())&(ROW()-4))} -> 30.25 | F17: {=INDIRECT("'"&$B$3&"'!"&CHAR(64+COLUMN())&(ROW()-4))} -> 74532 | G17: {=INDIRECT("'"&$B$3&"'!"&CHAR(64+COLUMN())&(ROW()-4))} -> -0.32948929 | H17: {=INDIRECT("'"&$B$3&"'!"&CHAR(64+COLUMN())&(ROW()-4))} -> 29.79 | ... O17: {=INDIRECT("'"&$B$3&"'!"&CHAR(64+COLUMN())&(ROW()-4))} -> 0.27424755 | Q17: 隔日參考價位
A18: {=INDIRECT("'"&$B$3&"'!"&CHAR(64+COLUMN())&(ROW()-4))} -> 46133 | B18: {=INDIRECT("'"&$B$3&"'!"&CHAR(64+COLUMN())&(ROW()-4))} -> 37605.11 | C18: {=INDIRECT("'"&$B$3&"'!"&CHAR(64+COLUMN())&(ROW()-4))} -> 31.95 | D18: {=INDIRECT("'"&$B$3&"'!"&CHAR(64+COLUMN())&(ROW()-4))} -> 30.75 | E18: {=INDIRECT("'"&$B$3&"'!"&CHAR(64+COLUMN())&(ROW()-4))} -> 31.45 | F18: {=INDIRECT("'"&$B$3&"'!"&CHAR(64+COLUMN())&(ROW()-4))} -> 89706 | G18: {=INDIRECT("'"&$B$3&"'!"&CHAR(64+COLUMN())&(ROW()-4))} -> 3.9669421 | H18: {=INDIRECT("'"&$B$3&"'!"&CHAR(64+COLUMN())&(ROW()-4))} -> 30.18 | ... O18: {=INDIRECT("'"&$B$3&"'!"&CHAR(64+COLUMN())&(ROW()-4))} -> 0.37400097 | Q18: 區間 | R18: 技術依據 | S18: 下緣 | T18: 上緣
A19: {=INDIRECT("'"&$B$3&"'!"&CHAR(64+COLUMN())&(ROW()-4))} -> 46134 | B19: {=INDIRECT("'"&$B$3&"'!"&CHAR(64+COLUMN())&(ROW()-4))} -> 37878.47 | C19: {=INDIRECT("'"&$B$3&"'!"&CHAR(64+COLUMN())&(ROW()-4))} -> 33.25 | D19: {=INDIRECT("'"&$B$3&"'!"&CHAR(64+COLUMN())&(ROW()-4))} -> 31.55 | E19: {=INDIRECT("'"&$B$3&"'!"&CHAR(64+COLUMN())&(ROW()-4))} -> 32.75 | F19: {=INDIRECT("'"&$B$3&"'!"&CHAR(64+COLUMN())&(ROW()-4))} -> 109771 | G19: {=INDIRECT("'"&$B$3&"'!"&CHAR(64+COLUMN())&(ROW()-4))} -> 4.1335453 | H19: {=INDIRECT("'"&$B$3&"'!"&CHAR(64+COLUMN())&(ROW()-4))} -> 30.84 | ... O19: {=INDIRECT("'"&$B$3&"'!"&CHAR(64+COLUMN())&(ROW()-4))} -> 0.5048769 | Q19: 🟢 積極買進 | R19: -1σ 統計下緣 | S19: =IF(LEFT($S$15,1)="🟢",ROUND(E25*(1-N32*1.2),1),"—") -> — | T19: =IF(LEFT($S$15,1)="🟢",ROUND(E25*(1-N32*0.8),1),"—") -> —
A20: {=INDIRECT("'"&$B$3&"'!"&CHAR(64+COLUMN())&(ROW()-4))} -> 46135 | B20: {=INDIRECT("'"&$B$3&"'!"&CHAR(64+COLUMN())&(ROW()-4))} -> 37714.15 | C20: {=INDIRECT("'"&$B$3&"'!"&CHAR(64+COLUMN())&(ROW()-4))} -> 33.55 | D20: {=INDIRECT("'"&$B$3&"'!"&CHAR(64+COLUMN())&(ROW()-4))} -> 30.6 | E20: {=INDIRECT("'"&$B$3&"'!"&CHAR(64+COLUMN())&(ROW()-4))} -> 31.2 | F20: {=INDIRECT("'"&$B$3&"'!"&CHAR(64+COLUMN())&(ROW()-4))} -> 76327 | G20: {=INDIRECT("'"&$B$3&"'!"&CHAR(64+COLUMN())&(ROW()-4))} -> -4.7328244 | H20: {=INDIRECT("'"&$B$3&"'!"&CHAR(64+COLUMN())&(ROW()-4))} -> 31.2 | ... O20: {=INDIRECT("'"&$B$3&"'!"&CHAR(64+COLUMN())&(ROW()-4))} -> 0.46536803 | Q20: 🟡 較安全買點 | R20: -1.5σ 跌深區 | S20: =IF(LEFT($S$15,1)="🟢",ROUND(E25*(1-N32*1.8),1),"—") -> — | T20: =IF(LEFT($S$15,1)="🟢",ROUND(E25*(1-N32*1.4),1),"—") -> —
A21: {=INDIRECT("'"&$B$3&"'!"&CHAR(64+COLUMN())&(ROW()-4))} -> 46136 | B21: {=INDIRECT("'"&$B$3&"'!"&CHAR(64+COLUMN())&(ROW()-4))} -> 38932.4 | C21: {=INDIRECT("'"&$B$3&"'!"&CHAR(64+COLUMN())&(ROW()-4))} -> 31.3 | D21: {=INDIRECT("'"&$B$3&"'!"&CHAR(64+COLUMN())&(ROW()-4))} -> 30 | E21: {=INDIRECT("'"&$B$3&"'!"&CHAR(64+COLUMN())&(ROW()-4))} -> 30.3 | F21: {=INDIRECT("'"&$B$3&"'!"&CHAR(64+COLUMN())&(ROW()-4))} -> 35382 | G21: {=INDIRECT("'"&$B$3&"'!"&CHAR(64+COLUMN())&(ROW()-4))} -> -2.8846154 | H21: {=INDIRECT("'"&$B$3&"'!"&CHAR(64+COLUMN())&(ROW()-4))} -> 31.19 | ... O21: {=INDIRECT("'"&$B$3&"'!"&CHAR(64+COLUMN())&(ROW()-4))} -> 0.3615572 | Q21: 🔵 強支撐買點 | R21: -2σ 強支撐 | S21: =IF(LEFT($S$15,1)="🟢",ROUND(E25*(1-N32*2.4),1),"—") -> — | T21: =IF(LEFT($S$15,1)="🟢",ROUND(E25*(1-N32*2),1),"—") -> —
A22: {=INDIRECT("'"&$B$3&"'!"&CHAR(64+COLUMN())&(ROW()-4))} -> 46139 | B22: {=INDIRECT("'"&$B$3&"'!"&CHAR(64+COLUMN())&(ROW()-4))} -> 39616.63 | C22: {=INDIRECT("'"&$B$3&"'!"&CHAR(64+COLUMN())&(ROW()-4))} -> 30.65 | D22: {=INDIRECT("'"&$B$3&"'!"&CHAR(64+COLUMN())&(ROW()-4))} -> 29.5 | E22: {=INDIRECT("'"&$B$3&"'!"&CHAR(64+COLUMN())&(ROW()-4))} -> 30 | F22: {=INDIRECT("'"&$B$3&"'!"&CHAR(64+COLUMN())&(ROW()-4))} -> 34784 | G22: {=INDIRECT("'"&$B$3&"'!"&CHAR(64+COLUMN())&(ROW()-4))} -> -0.99009901 | H22: {=INDIRECT("'"&$B$3&"'!"&CHAR(64+COLUMN())&(ROW()-4))} -> 31.14 | ... O22: {=INDIRECT("'"&$B$3&"'!"&CHAR(64+COLUMN())&(ROW()-4))} -> 0.26035162 | Q22: 🟡 小反彈賣 | R22: MA5 壓力 | S22: =IF(OR(AND(LEFT($S$15,1)="🔴",RIGHT($S$15,2)="出場"),AND($S$15="🔴 觀望",$S$12="🔴")),ROUND(MIN(H25,E25*(1+N32*0.8)),1),"—") -> 29.6 | T22: =IF(OR(AND(LEFT($S$15,1)="🔴",RIGHT($S$15,2)="出場"),AND($S$15="🔴 觀望",$S$12="🔴")),ROUND(MAX(H25,E25*(1+N32*1.2)),1),"—") -> 29.9
A23: {=INDIRECT("'"&$B$3&"'!"&CHAR(64+COLUMN())&(ROW()-4))} -> 46140 | B23: {=INDIRECT("'"&$B$3&"'!"&CHAR(64+COLUMN())&(ROW()-4))} -> 39521.73 | C23: {=INDIRECT("'"&$B$3&"'!"&CHAR(64+COLUMN())&(ROW()-4))} -> 30.45 | D23: {=INDIRECT("'"&$B$3&"'!"&CHAR(64+COLUMN())&(ROW()-4))} -> 29.6 | E23: {=INDIRECT("'"&$B$3&"'!"&CHAR(64+COLUMN())&(ROW()-4))} -> 29.85 | F23: {=INDIRECT("'"&$B$3&"'!"&CHAR(64+COLUMN())&(ROW()-4))} -> 45089 | G23: {=INDIRECT("'"&$B$3&"'!"&CHAR(64+COLUMN())&(ROW()-4))} -> -0.5 | H23: {=INDIRECT("'"&$B$3&"'!"&CHAR(64+COLUMN())&(ROW()-4))} -> 30.82 | ... O23: {=INDIRECT("'"&$B$3&"'!"&CHAR(64+COLUMN())&(ROW()-4))} -> 0.17506358 | Q23: 🔴 較佳出場 | R23: MA10 強壓 | S23: =IF(OR(AND(LEFT($S$15,1)="🔴",RIGHT($S$15,2)="出場"),AND($S$15="🔴 觀望",$S$12="🔴")),ROUND(MIN(I25,E25*(1+N32*1.4)),1),"—") -> 30.1 | T23: =IF(OR(AND(LEFT($S$15,1)="🔴",RIGHT($S$15,2)="出場"),AND($S$15="🔴 觀望",$S$12="🔴")),ROUND(MAX(I25,E25*(1+N32*1.8)),1),"—") -> 30.5
A24: {=INDIRECT("'"&$B$3&"'!"&CHAR(64+COLUMN())&(ROW()-4))} -> 46141 | B24: {=INDIRECT("'"&$B$3&"'!"&CHAR(64+COLUMN())&(ROW()-4))} -> 39303.5 | C24: {=INDIRECT("'"&$B$3&"'!"&CHAR(64+COLUMN())&(ROW()-4))} -> 30.15 | D24: {=INDIRECT("'"&$B$3&"'!"&CHAR(64+COLUMN())&(ROW()-4))} -> 29.3 | E24: {=INDIRECT("'"&$B$3&"'!"&CHAR(64+COLUMN())&(ROW()-4))} -> 29.7 | F24: {=INDIRECT("'"&$B$3&"'!"&CHAR(64+COLUMN())&(ROW()-4))} -> 29810 | G24: {=INDIRECT("'"&$B$3&"'!"&CHAR(64+COLUMN())&(ROW()-4))} -> -0.50251256 | H24: {=INDIRECT("'"&$B$3&"'!"&CHAR(64+COLUMN())&(ROW()-4))} -> 30.21 | ... O24: {=INDIRECT("'"&$B$3&"'!"&CHAR(64+COLUMN())&(ROW()-4))} -> 0.10382428 | Q24: ⚠️ 突破關鍵 | R24: 站上該價燈號轉強 | S24: =IF(OR(AND(LEFT($S$15,1)="🔴",RIGHT($S$15,2)="出場"),AND($S$15="🔴 觀望",$S$12="🔴")),ROUND(MAX(I25,E25*(1+N32*2)),1),"—") -> 30.5 | T24: =IF(OR(AND(LEFT($S$15,1)="🔴",RIGHT($S$15,2)="出場"),AND($S$15="🔴 觀望",$S$12="🔴")),ROUND(E25*(1+N32*2.4),1),"—") -> 30.8
A25: {=INDIRECT("'"&$B$3&"'!"&CHAR(64+COLUMN())&(ROW()-4))} -> 46142 | B25: {=INDIRECT("'"&$B$3&"'!"&CHAR(64+COLUMN())&(ROW()-4))} -> 38926.63 | C25: {=INDIRECT("'"&$B$3&"'!"&CHAR(64+COLUMN())&(ROW()-4))} -> 29.55 | D25: {=INDIRECT("'"&$B$3&"'!"&CHAR(64+COLUMN())&(ROW()-4))} -> 29 | E25: {=INDIRECT("'"&$B$3&"'!"&CHAR(64+COLUMN())&(ROW()-4))} -> 29 | F25: {=INDIRECT("'"&$B$3&"'!"&CHAR(64+COLUMN())&(ROW()-4))} -> 24600 | G25: {=INDIRECT("'"&$B$3&"'!"&CHAR(64+COLUMN())&(ROW()-4))} -> -2.3569024 | H25: {=INDIRECT("'"&$B$3&"'!"&CHAR(64+COLUMN())&(ROW()-4))} -> 29.77 | ... O25: {=INDIRECT("'"&$B$3&"'!"&CHAR(64+COLUMN())&(ROW()-4))} -> 0.0097885866 | Q25: 說明 | R25: =IF(LEFT($S$15,1)="🟢","燈號偏多→顯示買進區間（以收盤 "&TEXT(E25,"0.0")&"、σ="&TEXT(N32,"0.00%")&"）",IF(OR(AND(LEFT($S$15,1)="🔴",RIGHT($S$15,2)="出場"),AND($S$15="🔴 觀望",$S$12="🔴")),"燈號偏空→顯示賣出區間（以收盤 "&TEXT(E25,"0.0")&"、σ="&TEXT(N32,"0.00%")&"）","目前燈號為「"&$S$15&"」，建議等待、不推薦進出場")) -> 燈號偏空→顯示賣出區間（以收盤 29.0、σ=2.64%）
Q26: 距離預警 | R26: 目標價 | S26: 距現價 | T26: 說明
A27: 2025年 各季 EPS（元） | G27: 2026年 各季 EPS（元） | M27: 摘要統計 | Q27: 🟢 至買進區 | R27: =ROUND(E25*(1-N32),1) -> 28.2 | S27: =ROUND((E25*(1-N32)-E25)/E25,4) -> -0.0264 | T27: ="再跌 "&TEXT(ABS((E25*(1-N32)-E25)/E25),"0.0%")&" 至 "&TEXT(E25*(1-N32),"0.0")&" 進入積極買進區" -> 再跌 2.6% 至 28.2 進入積極買進區
A28: 季別 | B28: Q1 | C28: Q2 | D28: Q3 | E28: Q4 | G28: 季別 | H28: Q1 | I28: Q2 | J28: Q3 | K28: Q4 | M28: 最高價 | N28: =MAX(C6:C25) -> 33.55 | Q28: 🔴 至賣出區 | R28: =ROUND(MAX(H25,E25*(1+N32)),1) -> 29.8 | S28: =ROUND((MAX(H25,E25*(1+N32))-E25)/E25,4) -> 0.0266 | T28: ="再漲 "&TEXT(ABS((MAX(H25,E25*(1+N32))-E25)/E25),"0.0%")&" 至 "&TEXT(MAX(H25,E25*(1+N32)),"0.0")&" 進入反彈賣出區" -> 再漲 2.7% 至 29.8 進入反彈賣出區
A29: 單季 EPS | B29: 0.5 | C29: 0.11 | D29: 0.45 | E29: 0.32 | G29: 單季 EPS | M29: 最低價 | N29: =MIN(D6:D25) -> 26.75
A30: 全年合計 | B30: 1.38 | G30: 全年合計 | M30: 平均收盤 | N30: =AVERAGE(E6:E25) -> 29.365
A31: 季變化 | B31: — | C31: -0.78 | D31: 3.0909091 | E31: -0.28888889 | G31: 季變化 | H31: — | M31: 15日漲幅 | N31: =(E25-E6)/E6 -> 0.056466302
A32: 來源：Yahoo奇摩股市（非官方第三方） | M32: 波動率 | N32: =STDEV(G7:G25)/100 -> 0.026361107
A33: 2324 仁寶 ─ 股價合理性評估 | G33: 股價合理性評估（三法平均） | M33: 最新收盤 | N33: =E25 -> 29
A34: 股利 | B34: 1.1 | H34: 便宜價 | I34: 合理價 | J34: 貴價
A35: 每股淨值 | B35: 30.25 | G35: PER 法 | H35: =B36*B30 -> 11.04 | I35: =C36*B30 -> 16.56 | J35: =D36*B30 -> 24.84
A36: PER 倍數 | B36: 8 | C36: 12 | D36: 18 | G36: PBR 法 | H36: =B37*B35 -> 24.2 | I36: =C37*B35 -> 36.3 | J36: =D37*B35 -> 54.45
A37: PBR 倍數 | B37: 0.8 | C37: 1.2 | D37: 1.8 | G37: 殖利率法 | H37: =B34/B38 -> 18.333333 | I37: =B34/C38 -> 24.444444 | J37: =B34/D38 -> 36.666667
A38: 殖利率 | B38: 0.06 | C38: 0.045 | D38: 0.03 | G38: 三法平均 | H38: =AVERAGE(H35,H36,H37) -> 17.857778 | I38: =AVERAGE(I35,I36,I37) -> 25.768148 | J38: =AVERAGE(J35,J36,J37) -> 38.652222

Sheet 2382 廣達
A1: 2382 廣達 - 近20日股價追蹤
A2: 所屬產業： | B2: AI伺服器/筆電
A3: 資料來源： | B3: 2382
A5: 日期 | B5: 大盤 | C5: 最高 | D5: 最低 | E5: 收盤 | F5: 成交量(張) | G5: 漲跌幅 | H5: MA5 | I5: MA10 | J5: MA20 | K5: RSI(6) | L5: RSI(12) | M5: KD-K | N5: KD-D | O5: MACD-OSC | Q5: 燈號儀表板
A6: {=INDIRECT("'"&$B$3&"'!"&CHAR(64+COLUMN())&(ROW()-4))} -> 46113 | B6: {=INDIRECT("'"&$B$3&"'!"&CHAR(64+COLUMN())&(ROW()-4))} -> 33174.82 | C6: {=INDIRECT("'"&$B$3&"'!"&CHAR(64+COLUMN())&(ROW()-4))} -> 291 | D6: {=INDIRECT("'"&$B$3&"'!"&CHAR(64+COLUMN())&(ROW()-4))} -> 285 | E6: {=INDIRECT("'"&$B$3&"'!"&CHAR(64+COLUMN())&(ROW()-4))} -> 290.5 | F6: {=INDIRECT("'"&$B$3&"'!"&CHAR(64+COLUMN())&(ROW()-4))} -> 18751 | G6: {=INDIRECT("'"&$B$3&"'!"&CHAR(64+COLUMN())&(ROW()-4))} -> 4.3087971 | H6: {=INDIRECT("'"&$B$3&"'!"&CHAR(64+COLUMN())&(ROW()-4))} -> 285.2 | ... O6: {=INDIRECT("'"&$B$3&"'!"&CHAR(64+COLUMN())&(ROW()-4))} -> -0.32147255 | Q6: 步驟 | R6: 條件 | S6: 燈號 | T6: 細節
A7: {=INDIRECT("'"&$B$3&"'!"&CHAR(64+COLUMN())&(ROW()-4))} -> 46114 | B7: {=INDIRECT("'"&$B$3&"'!"&CHAR(64+COLUMN())&(ROW()-4))} -> 32572.43 | C7: {=INDIRECT("'"&$B$3&"'!"&CHAR(64+COLUMN())&(ROW()-4))} -> 291.5 | D7: {=INDIRECT("'"&$B$3&"'!"&CHAR(64+COLUMN())&(ROW()-4))} -> 284.5 | E7: {=INDIRECT("'"&$B$3&"'!"&CHAR(64+COLUMN())&(ROW()-4))} -> 284.5 | F7: {=INDIRECT("'"&$B$3&"'!"&CHAR(64+COLUMN())&(ROW()-4))} -> 11221 | G7: {=INDIRECT("'"&$B$3&"'!"&CHAR(64+COLUMN())&(ROW()-4))} -> -2.0654045 | H7: {=INDIRECT("'"&$B$3&"'!"&CHAR(64+COLUMN())&(ROW()-4))} -> 284.7 | ... O7: {=INDIRECT("'"&$B$3&"'!"&CHAR(64+COLUMN())&(ROW()-4))} -> -0.30306605 | Q7: 1 | R7: 大盤過濾（大盤 > 自身 MA20） | S7: =IF(COUNT(B6:B25)<5,"⚪",IF(AND(B25>AVERAGE(B6:B25),B25>B20),"🟢",IF(OR(B25>AVERAGE(B6:B25),B25>B20),"🟡","🔴"))) -> 🟢 | T7: =IF(COUNT(B6:B25)<5,"大盤資料不足","大盤="&TEXT(B25,"#,##0")&" vs MA="&TEXT(AVERAGE(B6:B25),"#,##0")&" 斜率:"&IF(B25>B20,"↑","↓")) -> 大盤=38,927 vs MA=36,644 斜率:↑
A8: {=INDIRECT("'"&$B$3&"'!"&CHAR(64+COLUMN())&(ROW()-4))} -> 46119 | B8: {=INDIRECT("'"&$B$3&"'!"&CHAR(64+COLUMN())&(ROW()-4))} -> 33229.82 | C8: {=INDIRECT("'"&$B$3&"'!"&CHAR(64+COLUMN())&(ROW()-4))} -> 289.5 | D8: {=INDIRECT("'"&$B$3&"'!"&CHAR(64+COLUMN())&(ROW()-4))} -> 284 | E8: {=INDIRECT("'"&$B$3&"'!"&CHAR(64+COLUMN())&(ROW()-4))} -> 289 | F8: {=INDIRECT("'"&$B$3&"'!"&CHAR(64+COLUMN())&(ROW()-4))} -> 9060 | G8: {=INDIRECT("'"&$B$3&"'!"&CHAR(64+COLUMN())&(ROW()-4))} -> 1.5817223 | H8: {=INDIRECT("'"&$B$3&"'!"&CHAR(64+COLUMN())&(ROW()-4))} -> 284.7 | ... O8: {=INDIRECT("'"&$B$3&"'!"&CHAR(64+COLUMN())&(ROW()-4))} -> 0.010389807 | Q8: 2 | R8: 趨勢結構（MA10>MA20 且 MA20 斜率向上） | S8: =IF(OR(I25="",J25="",J20=""),"⚪",IF(AND(I25>J25,J25>J20),"🟢",IF(OR(I25>J25,J25>J20),"🟡","🔴"))) -> 🟢 | T8: =IF(OR(I25="",J25="",J20=""),"資料不足","MA10=" &TEXT(I25,"0.0")& " MA20=" &TEXT(J25,"0.0")& " " &IF(I25>J25,"多頭","空頭")& " 斜率:" &IF(J25>J20,"↑","↓")) -> MA10=325.3 MA20=316.4 多頭 斜率:↑
A9: {=INDIRECT("'"&$B$3&"'!"&CHAR(64+COLUMN())&(ROW()-4))} -> 46120 | B9: {=INDIRECT("'"&$B$3&"'!"&CHAR(64+COLUMN())&(ROW()-4))} -> 34761.38 | C9: {=INDIRECT("'"&$B$3&"'!"&CHAR(64+COLUMN())&(ROW()-4))} -> 307.5 | D9: {=INDIRECT("'"&$B$3&"'!"&CHAR(64+COLUMN())&(ROW()-4))} -> 293.5 | E9: {=INDIRECT("'"&$B$3&"'!"&CHAR(64+COLUMN())&(ROW()-4))} -> 307.5 | F9: {=INDIRECT("'"&$B$3&"'!"&CHAR(64+COLUMN())&(ROW()-4))} -> 54410 | G9: {=INDIRECT("'"&$B$3&"'!"&CHAR(64+COLUMN())&(ROW()-4))} -> 6.4013841 | H9: {=INDIRECT("'"&$B$3&"'!"&CHAR(64+COLUMN())&(ROW()-4))} -> 290 | ... O9: {=INDIRECT("'"&$B$3&"'!"&CHAR(64+COLUMN())&(ROW()-4))} -> 1.3857686 | Q9: 3 | R9: 動能三合（MA5>MA10 + KD金叉 + RSI6>50） | S9: =IF(OR(H25="",I25="",K25="",M25="",N25="",K24="",M24="",N24=""),"⚪",IF(AND(H25>I25,M25>N25,K25>50,OR(AND(M24<N24,M25>N25,M24<50),AND(K24<50,K25>=50),AND(M24<50,M25>=50))),"🟢",IF(AND(H25>I25,M25>N25,K25>50),"🟡",IF(SUM(IF(H25>I25,1,0),IF(M25>N25,1,0),IF(K25>50,1,0))>=2,"🟡","🔴")))) -> 🔴 | T9: ="MA金叉:"&IF(H25>I25,"✓","✗")&" KD金叉:"&IF(AND(M24<N24,M25>N25),"✓","✗")&"(K="&TEXT(M25,"0")&") RSI6:"&TEXT(K25,"0")&IF(AND(K24<50,K25>=50),"(首破50)","") -> MA金叉:✗ KD金叉:✗(K=26) RSI6:37
A10: {=INDIRECT("'"&$B$3&"'!"&CHAR(64+COLUMN())&(ROW()-4))} -> 46121 | B10: {=INDIRECT("'"&$B$3&"'!"&CHAR(64+COLUMN())&(ROW()-4))} -> 34861.16 | C10: {=INDIRECT("'"&$B$3&"'!"&CHAR(64+COLUMN())&(ROW()-4))} -> 314 | D10: {=INDIRECT("'"&$B$3&"'!"&CHAR(64+COLUMN())&(ROW()-4))} -> 295 | E10: {=INDIRECT("'"&$B$3&"'!"&CHAR(64+COLUMN())&(ROW()-4))} -> 313 | F10: {=INDIRECT("'"&$B$3&"'!"&CHAR(64+COLUMN())&(ROW()-4))} -> 46807 | G10: {=INDIRECT("'"&$B$3&"'!"&CHAR(64+COLUMN())&(ROW()-4))} -> 1.7886179 | H10: {=INDIRECT("'"&$B$3&"'!"&CHAR(64+COLUMN())&(ROW()-4))} -> 296.9 | ... O10: {=INDIRECT("'"&$B$3&"'!"&CHAR(64+COLUMN())&(ROW()-4))} -> 2.5218525 | Q10: 4 | R10: 量能（≥1.5×5日均量） | S10: =IF(F25="","⚪",IF(S9="🟢",IF(F25>=1.5*AVERAGE(F20:F24),"🟢",IF(F25>=AVERAGE(F20:F24),"🟡","🔴")),IF(S12="🟢",IF(AND(E25>E24,F25<F24),"🔴",IF(F25>=AVERAGE(F20:F24),"🟢","🟡")),IF(F25>=1.5*AVERAGE(F20:F24),"🟢",IF(F25>=AVERAGE(F20:F24),"🟡","🔴"))))) -> 🟡 | T10: ="今量="&TEXT(F25,"#,##0")&" 5日均="&TEXT(AVERAGE(F20:F24),"#,##0")&" 比值="&TEXT(F25/AVERAGE(F20:F24),"0.00")&"x"&IF(AND(E25>E24,F25<F24)," ⚠價漲量縮","") -> 今量=18,917 5日均=17,993 比值=1.05x
A11: {=INDIRECT("'"&$B$3&"'!"&CHAR(64+COLUMN())&(ROW()-4))} -> 46122 | B11: {=INDIRECT("'"&$B$3&"'!"&CHAR(64+COLUMN())&(ROW()-4))} -> 35417.83 | C11: {=INDIRECT("'"&$B$3&"'!"&CHAR(64+COLUMN())&(ROW()-4))} -> 327.5 | D11: {=INDIRECT("'"&$B$3&"'!"&CHAR(64+COLUMN())&(ROW()-4))} -> 312 | E11: {=INDIRECT("'"&$B$3&"'!"&CHAR(64+COLUMN())&(ROW()-4))} -> 321.5 | F11: {=INDIRECT("'"&$B$3&"'!"&CHAR(64+COLUMN())&(ROW()-4))} -> 39034 | G11: {=INDIRECT("'"&$B$3&"'!"&CHAR(64+COLUMN())&(ROW()-4))} -> 2.715655 | H11: {=INDIRECT("'"&$B$3&"'!"&CHAR(64+COLUMN())&(ROW()-4))} -> 303.1 | ... O11: {=INDIRECT("'"&$B$3&"'!"&CHAR(64+COLUMN())&(ROW()-4))} -> 3.6341006 | Q11: 5 | R11: 停損參考（三段） | S11: — | T11: ="緊 MA10=" & TEXT(I25,"0.0") & " 中 -" & TEXT(IF(N32<0.025,5,IF(N32<0.04,6,8)),"0") & "%=" & TEXT(E25*(1-IF(N32<0.025,0.05,IF(N32<0.04,0.06,0.08))),"0.0") & " 鬆 MA20=" & TEXT(J25,"0.0") & " (σ=" & TEXT(N32,"0.0%") & ")" -> 緊 MA10=325.3 中 -6%=293.8 鬆 MA20=316.4 (σ=2.7%)
A12: {=INDIRECT("'"&$B$3&"'!"&CHAR(64+COLUMN())&(ROW()-4))} -> 46125 | B12: {=INDIRECT("'"&$B$3&"'!"&CHAR(64+COLUMN())&(ROW()-4))} -> 35457.29 | C12: {=INDIRECT("'"&$B$3&"'!"&CHAR(64+COLUMN())&(ROW()-4))} -> 320.5 | D12: {=INDIRECT("'"&$B$3&"'!"&CHAR(64+COLUMN())&(ROW()-4))} -> 313 | E12: {=INDIRECT("'"&$B$3&"'!"&CHAR(64+COLUMN())&(ROW()-4))} -> 319 | F12: {=INDIRECT("'"&$B$3&"'!"&CHAR(64+COLUMN())&(ROW()-4))} -> 16849 | G12: {=INDIRECT("'"&$B$3&"'!"&CHAR(64+COLUMN())&(ROW()-4))} -> -0.77760498 | H12: {=INDIRECT("'"&$B$3&"'!"&CHAR(64+COLUMN())&(ROW()-4))} -> 310 | ... O12: {=INDIRECT("'"&$B$3&"'!"&CHAR(64+COLUMN())&(ROW()-4))} -> 3.962826 | Q12: 6 | R12: 持有訊號（收盤>MA5） | S12: =IF(OR(E25="",H25=""),"⚪",IF(E25>H25,"🟢",IF(AND(E25<H25,E24<H24),"🔴","🟡"))) -> 🔴 | T12: ="收盤="&TEXT(E25,"0.0")&" MA5="&TEXT(H25,"0.0")&IF(E25>H25," 守穩",IF(AND(E25<H25,E24<H24)," 連2日跌破"," 單日跌破(警示)")) -> 收盤=312.5 MA5=320.8 連2日跌破
A13: {=INDIRECT("'"&$B$3&"'!"&CHAR(64+COLUMN())&(ROW()-4))} -> 46126 | B13: {=INDIRECT("'"&$B$3&"'!"&CHAR(64+COLUMN())&(ROW()-4))} -> 36296.12 | C13: {=INDIRECT("'"&$B$3&"'!"&CHAR(64+COLUMN())&(ROW()-4))} -> 329.5 | D13: {=INDIRECT("'"&$B$3&"'!"&CHAR(64+COLUMN())&(ROW()-4))} -> 321 | E13: {=INDIRECT("'"&$B$3&"'!"&CHAR(64+COLUMN())&(ROW()-4))} -> 323 | F13: {=INDIRECT("'"&$B$3&"'!"&CHAR(64+COLUMN())&(ROW()-4))} -> 20523 | G13: {=INDIRECT("'"&$B$3&"'!"&CHAR(64+COLUMN())&(ROW()-4))} -> 1.2539185 | H13: {=INDIRECT("'"&$B$3&"'!"&CHAR(64+COLUMN())&(ROW()-4))} -> 316.8 | ... O13: {=INDIRECT("'"&$B$3&"'!"&CHAR(64+COLUMN())&(ROW()-4))} -> 4.1890049 | Q13: 7 | R13: 出場警示（4取2） | S13: =IF(SUM(IF(AND(E25>MAX(E15:E24),K25<MAX(K15:K24)),1,0),IF(AND(E25>MAX(E15:E24),F25<MAX(F15:F24)),1,0),IF(AND(E25<H25,H25<H24),1,0),IF(AND(M24>N24,M25<N25,M24>80),1,0),IF(AND(E25<J25,E24<J24),1,0))>=2,"🔴",IF(SUM(IF(AND(E25>MAX(E15:E24),K25<MAX(K15:K24)),1,0),IF(AND(E25>MAX(E15:E24),F25<MAX(F15:F24)),1,0),IF(AND(E25<H25,H25<H24),1,0),IF(AND(M24>N24,M25<N25,M24>80),1,0),IF(AND(E25<J25,E24<J24),1,0))=1,"🟡","🟢")) -> 🟡 | T13: ="RSI背離:"&IF(AND(E25>MAX(E15:E24),K25<MAX(K15:K24)),"✓","✗")&" 量價背離:"&IF(AND(E25>MAX(E15:E24),F25<MAX(F15:F24)),"✓","✗")&" MA5翻下:"&IF(AND(E25<H25,H25<H24),"✓","✗")&" KD高死叉:"&IF(AND(M24>N24,M25<N25,M24>80),"✓","✗")&" 破MA20:"&IF(AND(E25<J25,E24<J24),"✓","✗") -> RSI背離:✗ 量價背離:✗ MA5翻下:✓ KD高死叉:✗ 破MA20:✗
A14: {=INDIRECT("'"&$B$3&"'!"&CHAR(64+COLUMN())&(ROW()-4))} -> 46127 | B14: {=INDIRECT("'"&$B$3&"'!"&CHAR(64+COLUMN())&(ROW()-4))} -> 36722.14 | C14: {=INDIRECT("'"&$B$3&"'!"&CHAR(64+COLUMN())&(ROW()-4))} -> 325 | D14: {=INDIRECT("'"&$B$3&"'!"&CHAR(64+COLUMN())&(ROW()-4))} -> 307 | E14: {=INDIRECT("'"&$B$3&"'!"&CHAR(64+COLUMN())&(ROW()-4))} -> 308.5 | F14: {=INDIRECT("'"&$B$3&"'!"&CHAR(64+COLUMN())&(ROW()-4))} -> 34222 | G14: {=INDIRECT("'"&$B$3&"'!"&CHAR(64+COLUMN())&(ROW()-4))} -> -4.4891641 | H14: {=INDIRECT("'"&$B$3&"'!"&CHAR(64+COLUMN())&(ROW()-4))} -> 317 | ... O14: {=INDIRECT("'"&$B$3&"'!"&CHAR(64+COLUMN())&(ROW()-4))} -> 3.1488787
A15: {=INDIRECT("'"&$B$3&"'!"&CHAR(64+COLUMN())&(ROW()-4))} -> 46128 | B15: {=INDIRECT("'"&$B$3&"'!"&CHAR(64+COLUMN())&(ROW()-4))} -> 37132.02 | C15: {=INDIRECT("'"&$B$3&"'!"&CHAR(64+COLUMN())&(ROW()-4))} -> 318.5 | D15: {=INDIRECT("'"&$B$3&"'!"&CHAR(64+COLUMN())&(ROW()-4))} -> 311 | E15: {=INDIRECT("'"&$B$3&"'!"&CHAR(64+COLUMN())&(ROW()-4))} -> 318.5 | F15: {=INDIRECT("'"&$B$3&"'!"&CHAR(64+COLUMN())&(ROW()-4))} -> 19430 | G15: {=INDIRECT("'"&$B$3&"'!"&CHAR(64+COLUMN())&(ROW()-4))} -> 3.2414911 | H15: {=INDIRECT("'"&$B$3&"'!"&CHAR(64+COLUMN())&(ROW()-4))} -> 318.1 | ... O15: {=INDIRECT("'"&$B$3&"'!"&CHAR(64+COLUMN())&(ROW()-4))} -> 2.9259378 | Q15: 總燈號 | R15: ="通過 "&(COUNTIF(S7:S13,"🟢"))&" / 7 警示 "&COUNTIF(S7:S13,"🟡")&" 危險 "&COUNTIF(S7:S13,"🔴") -> 通過 2 / 7 警示 2 危險 2 | S15: =IF(AND(S7="🟢",COUNTIF(S7:S10,"🟢")=4,S13<>"🔴"),"🟢 強進場",IF(AND(S7="🟢",COUNTIF(S7:S10,"🟢")>=3,S13<>"🔴"),"🟢 次強進場",IF(S13="🔴","🔴 出場",IF(COUNTIF(S7:S13,"🔴")>=2,"🔴 觀望","🟡 等待")))) -> 🔴 觀望 | T15: ="基於 "&TEXT(A25,"yyyy/mm/dd")&" 收盤資料" -> 基於 2026/04/30 收盤資料
A16: {=INDIRECT("'"&$B$3&"'!"&CHAR(64+COLUMN())&(ROW()-4))} -> 46129 | B16: {=INDIRECT("'"&$B$3&"'!"&CHAR(64+COLUMN())&(ROW()-4))} -> 36804.34 | C16: {=INDIRECT("'"&$B$3&"'!"&CHAR(64+COLUMN())&(ROW()-4))} -> 327.5 | D16: {=INDIRECT("'"&$B$3&"'!"&CHAR(64+COLUMN())&(ROW()-4))} -> 317.5 | E16: {=INDIRECT("'"&$B$3&"'!"&CHAR(64+COLUMN())&(ROW()-4))} -> 323 | F16: {=INDIRECT("'"&$B$3&"'!"&CHAR(64+COLUMN())&(ROW()-4))} -> 20083 | G16: {=INDIRECT("'"&$B$3&"'!"&CHAR(64+COLUMN())&(ROW()-4))} -> 1.4128728 | H16: {=INDIRECT("'"&$B$3&"'!"&CHAR(64+COLUMN())&(ROW()-4))} -> 318.4 | ... O16: {=INDIRECT("'"&$B$3&"'!"&CHAR(64+COLUMN())&(ROW()-4))} -> 2.8692138
A17: {=INDIRECT("'"&$B$3&"'!"&CHAR(64+COLUMN())&(ROW()-4))} -> 46132 | B17: {=INDIRECT("'"&$B$3&"'!"&CHAR(64+COLUMN())&(ROW()-4))} -> 36958.8 | C17: {=INDIRECT("'"&$B$3&"'!"&CHAR(64+COLUMN())&(ROW()-4))} -> 330.5 | D17: {=INDIRECT("'"&$B$3&"'!"&CHAR(64+COLUMN())&(ROW()-4))} -> 320 | E17: {=INDIRECT("'"&$B$3&"'!"&CHAR(64+COLUMN())&(ROW()-4))} -> 329 | F17: {=INDIRECT("'"&$B$3&"'!"&CHAR(64+COLUMN())&(ROW()-4))} -> 19861 | G17: {=INDIRECT("'"&$B$3&"'!"&CHAR(64+COLUMN())&(ROW()-4))} -> 1.8575851 | H17: {=INDIRECT("'"&$B$3&"'!"&CHAR(64+COLUMN())&(ROW()-4))} -> 320.4 | ... O17: {=INDIRECT("'"&$B$3&"'!"&CHAR(64+COLUMN())&(ROW()-4))} -> 3.008832 | Q17: 隔日參考價位
A18: {=INDIRECT("'"&$B$3&"'!"&CHAR(64+COLUMN())&(ROW()-4))} -> 46133 | B18: {=INDIRECT("'"&$B$3&"'!"&CHAR(64+COLUMN())&(ROW()-4))} -> 37605.11 | C18: {=INDIRECT("'"&$B$3&"'!"&CHAR(64+COLUMN())&(ROW()-4))} -> 341 | D18: {=INDIRECT("'"&$B$3&"'!"&CHAR(64+COLUMN())&(ROW()-4))} -> 332 | E18: {=INDIRECT("'"&$B$3&"'!"&CHAR(64+COLUMN())&(ROW()-4))} -> 340 | F18: {=INDIRECT("'"&$B$3&"'!"&CHAR(64+COLUMN())&(ROW()-4))} -> 24631 | G18: {=INDIRECT("'"&$B$3&"'!"&CHAR(64+COLUMN())&(ROW()-4))} -> 3.343465 | H18: {=INDIRECT("'"&$B$3&"'!"&CHAR(64+COLUMN())&(ROW()-4))} -> 323.8 | ... O18: {=INDIRECT("'"&$B$3&"'!"&CHAR(64+COLUMN())&(ROW()-4))} -> 3.5764252 | Q18: 區間 | R18: 技術依據 | S18: 下緣 | T18: 上緣
A19: {=INDIRECT("'"&$B$3&"'!"&CHAR(64+COLUMN())&(ROW()-4))} -> 46134 | B19: {=INDIRECT("'"&$B$3&"'!"&CHAR(64+COLUMN())&(ROW()-4))} -> 37878.47 | C19: {=INDIRECT("'"&$B$3&"'!"&CHAR(64+COLUMN())&(ROW()-4))} -> 345 | D19: {=INDIRECT("'"&$B$3&"'!"&CHAR(64+COLUMN())&(ROW()-4))} -> 333.5 | E19: {=INDIRECT("'"&$B$3&"'!"&CHAR(64+COLUMN())&(ROW()-4))} -> 335 | F19: {=INDIRECT("'"&$B$3&"'!"&CHAR(64+COLUMN())&(ROW()-4))} -> 18439 | G19: {=INDIRECT("'"&$B$3&"'!"&CHAR(64+COLUMN())&(ROW()-4))} -> -1.4705882 | H19: {=INDIRECT("'"&$B$3&"'!"&CHAR(64+COLUMN())&(ROW()-4))} -> 329.1 | ... O19: {=INDIRECT("'"&$B$3&"'!"&CHAR(64+COLUMN())&(ROW()-4))} -> 3.3532766 | Q19: 🟢 積極買進 | R19: -1σ 統計下緣 | S19: =IF(LEFT($S$15,1)="🟢",ROUND(E25*(1-N32*1.2),1),"—") -> — | T19: =IF(LEFT($S$15,1)="🟢",ROUND(E25*(1-N32*0.8),1),"—") -> —
A20: {=INDIRECT("'"&$B$3&"'!"&CHAR(64+COLUMN())&(ROW()-4))} -> 46135 | B20: {=INDIRECT("'"&$B$3&"'!"&CHAR(64+COLUMN())&(ROW()-4))} -> 37714.15 | C20: {=INDIRECT("'"&$B$3&"'!"&CHAR(64+COLUMN())&(ROW()-4))} -> 339 | D20: {=INDIRECT("'"&$B$3&"'!"&CHAR(64+COLUMN())&(ROW()-4))} -> 317 | E20: {=INDIRECT("'"&$B$3&"'!"&CHAR(64+COLUMN())&(ROW()-4))} -> 322 | F20: {=INDIRECT("'"&$B$3&"'!"&CHAR(64+COLUMN())&(ROW()-4))} -> 27349 | G20: {=INDIRECT("'"&$B$3&"'!"&CHAR(64+COLUMN())&(ROW()-4))} -> -3.880597 | H20: {=INDIRECT("'"&$B$3&"'!"&CHAR(64+COLUMN())&(ROW()-4))} -> 329.8 | ... O20: {=INDIRECT("'"&$B$3&"'!"&CHAR(64+COLUMN())&(ROW()-4))} -> 2.1280202 | Q20: 🟡 較安全買點 | R20: -1.5σ 跌深區 | S20: =IF(LEFT($S$15,1)="🟢",ROUND(E25*(1-N32*1.8),1),"—") -> — | T20: =IF(LEFT($S$15,1)="🟢",ROUND(E25*(1-N32*1.4),1),"—") -> —
A21: {=INDIRECT("'"&$B$3&"'!"&CHAR(64+COLUMN())&(ROW()-4))} -> 46136 | B21: {=INDIRECT("'"&$B$3&"'!"&CHAR(64+COLUMN())&(ROW()-4))} -> 38932.4 | C21: {=INDIRECT("'"&$B$3&"'!"&CHAR(64+COLUMN())&(ROW()-4))} -> 326.5 | D21: {=INDIRECT("'"&$B$3&"'!"&CHAR(64+COLUMN())&(ROW()-4))} -> 318 | E21: {=INDIRECT("'"&$B$3&"'!"&CHAR(64+COLUMN())&(ROW()-4))} -> 323 | F21: {=INDIRECT("'"&$B$3&"'!"&CHAR(64+COLUMN())&(ROW()-4))} -> 18393 | G21: {=INDIRECT("'"&$B$3&"'!"&CHAR(64+COLUMN())&(ROW()-4))} -> 0.31055901 | H21: {=INDIRECT("'"&$B$3&"'!"&CHAR(64+COLUMN())&(ROW()-4))} -> 329.8 | ... O21: {=INDIRECT("'"&$B$3&"'!"&CHAR(64+COLUMN())&(ROW()-4))} -> 1.2274889 | Q21: 🔵 強支撐買點 | R21: -2σ 強支撐 | S21: =IF(LEFT($S$15,1)="🟢",ROUND(E25*(1-N32*2.4),1),"—") -> — | T21: =IF(LEFT($S$15,1)="🟢",ROUND(E25*(1-N32*2),1),"—") -> —
A22: {=INDIRECT("'"&$B$3&"'!"&CHAR(64+COLUMN())&(ROW()-4))} -> 46139 | B22: {=INDIRECT("'"&$B$3&"'!"&CHAR(64+COLUMN())&(ROW()-4))} -> 39616.63 | C22: {=INDIRECT("'"&$B$3&"'!"&CHAR(64+COLUMN())&(ROW()-4))} -> 328.5 | D22: {=INDIRECT("'"&$B$3&"'!"&CHAR(64+COLUMN())&(ROW()-4))} -> 319.5 | E22: {=INDIRECT("'"&$B$3&"'!"&CHAR(64+COLUMN())&(ROW()-4))} -> 325.5 | F22: {=INDIRECT("'"&$B$3&"'!"&CHAR(64+COLUMN())&(ROW()-4))} -> 16453 | G22: {=INDIRECT("'"&$B$3&"'!"&CHAR(64+COLUMN())&(ROW()-4))} -> 0.77399381 | H22: {=INDIRECT("'"&$B$3&"'!"&CHAR(64+COLUMN())&(ROW()-4))} -> 329.1 | ... O22: {=INDIRECT("'"&$B$3&"'!"&CHAR(64+COLUMN())&(ROW()-4))} -> 0.67062534 | Q22: 🟡 小反彈賣 | R22: MA5 壓力 | S22: =IF(OR(AND(LEFT($S$15,1)="🔴",RIGHT($S$15,2)="出場"),AND($S$15="🔴 觀望",$S$12="🔴")),ROUND(MIN(H25,E25*(1+N32*0.8)),1),"—") -> 319.3 | T22: =IF(OR(AND(LEFT($S$15,1)="🔴",RIGHT($S$15,2)="出場"),AND($S$15="🔴 觀望",$S$12="🔴")),ROUND(MAX(H25,E25*(1+N32*1.2)),1),"—") -> 322.7
A23: {=INDIRECT("'"&$B$3&"'!"&CHAR(64+COLUMN())&(ROW()-4))} -> 46140 | B23: {=INDIRECT("'"&$B$3&"'!"&CHAR(64+COLUMN())&(ROW()-4))} -> 39521.73 | C23: {=INDIRECT("'"&$B$3&"'!"&CHAR(64+COLUMN())&(ROW()-4))} -> 330 | D23: {=INDIRECT("'"&$B$3&"'!"&CHAR(64+COLUMN())&(ROW()-4))} -> 317.5 | E23: {=INDIRECT("'"&$B$3&"'!"&CHAR(64+COLUMN())&(ROW()-4))} -> 321 | F23: {=INDIRECT("'"&$B$3&"'!"&CHAR(64+COLUMN())&(ROW()-4))} -> 15997 | G23: {=INDIRECT("'"&$B$3&"'!"&CHAR(64+COLUMN())&(ROW()-4))} -> -1.3824885 | H23: {=INDIRECT("'"&$B$3&"'!"&CHAR(64+COLUMN())&(ROW()-4))} -> 325.3 | ... O23: {=INDIRECT("'"&$B$3&"'!"&CHAR(64+COLUMN())&(ROW()-4))} -> -0.089894457 | Q23: 🔴 較佳出場 | R23: MA10 強壓 | S23: =IF(OR(AND(LEFT($S$15,1)="🔴",RIGHT($S$15,2)="出場"),AND($S$15="🔴 觀望",$S$12="🔴")),ROUND(MIN(I25,E25*(1+N32*1.4)),1),"—") -> 324.4 | T23: =IF(OR(AND(LEFT($S$15,1)="🔴",RIGHT($S$15,2)="出場"),AND($S$15="🔴 觀望",$S$12="🔴")),ROUND(MAX(I25,E25*(1+N32*1.8)),1),"—") -> 327.8
A24: {=INDIRECT("'"&$B$3&"'!"&CHAR(64+COLUMN())&(ROW()-4))} -> 46141 | B24: {=INDIRECT("'"&$B$3&"'!"&CHAR(64+COLUMN())&(ROW()-4))} -> 39303.5 | C24: {=INDIRECT("'"&$B$3&"'!"&CHAR(64+COLUMN())&(ROW()-4))} -> 322 | D24: {=INDIRECT("'"&$B$3&"'!"&CHAR(64+COLUMN())&(ROW()-4))} -> 317 | E24: {=INDIRECT("'"&$B$3&"'!"&CHAR(64+COLUMN())&(ROW()-4))} -> 322 | F24: {=INDIRECT("'"&$B$3&"'!"&CHAR(64+COLUMN())&(ROW()-4))} -> 11774 | G24: {=INDIRECT("'"&$B$3&"'!"&CHAR(64+COLUMN())&(ROW()-4))} -> 0.31152648 | H24: {=INDIRECT("'"&$B$3&"'!"&CHAR(64+COLUMN())&(ROW()-4))} -> 322.7 | ... O24: {=INDIRECT("'"&$B$3&"'!"&CHAR(64+COLUMN())&(ROW()-4))} -> -0.58699228 | Q24: ⚠️ 突破關鍵 | R24: 站上該價燈號轉強 | S24: =IF(OR(AND(LEFT($S$15,1)="🔴",RIGHT($S$15,2)="出場"),AND($S$15="🔴 觀望",$S$12="🔴")),ROUND(MAX(I25,E25*(1+N32*2)),1),"—") -> 329.5 | T24: =IF(OR(AND(LEFT($S$15,1)="🔴",RIGHT($S$15,2)="出場"),AND($S$15="🔴 觀望",$S$12="🔴")),ROUND(E25*(1+N32*2.4),1),"—") -> 332.9
A25: {=INDIRECT("'"&$B$3&"'!"&CHAR(64+COLUMN())&(ROW()-4))} -> 46142 | B25: {=INDIRECT("'"&$B$3&"'!"&CHAR(64+COLUMN())&(ROW()-4))} -> 38926.63 | C25: {=INDIRECT("'"&$B$3&"'!"&CHAR(64+COLUMN())&(ROW()-4))} -> 321 | D25: {=INDIRECT("'"&$B$3&"'!"&CHAR(64+COLUMN())&(ROW()-4))} -> 312 | E25: {=INDIRECT("'"&$B$3&"'!"&CHAR(64+COLUMN())&(ROW()-4))} -> 312.5 | F25: {=INDIRECT("'"&$B$3&"'!"&CHAR(64+COLUMN())&(ROW()-4))} -> 18917 | G25: {=INDIRECT("'"&$B$3&"'!"&CHAR(64+COLUMN())&(ROW()-4))} -> -2.9503106 | H25: {=INDIRECT("'"&$B$3&"'!"&CHAR(64+COLUMN())&(ROW()-4))} -> 320.8 | ... O25: {=INDIRECT("'"&$B$3&"'!"&CHAR(64+COLUMN())&(ROW()-4))} -> -1.5616712 | Q25: 說明 | R25: =IF(LEFT($S$15,1)="🟢","燈號偏多→顯示買進區間（以收盤 "&TEXT(E25,"0.0")&"、σ="&TEXT(N32,"0.00%")&"）",IF(OR(AND(LEFT($S$15,1)="🔴",RIGHT($S$15,2)="出場"),AND($S$15="🔴 觀望",$S$12="🔴")),"燈號偏空→顯示賣出區間（以收盤 "&TEXT(E25,"0.0")&"、σ="&TEXT(N32,"0.00%")&"）","目前燈號為「"&$S$15&"」，建議等待、不推薦進出場")) -> 燈號偏空→顯示賣出區間（以收盤 312.5、σ=2.72%）
Q26: 距離預警 | R26: 目標價 | S26: 距現價 | T26: 說明
A27: 2025年 各季 EPS（元） | G27: 2026年 各季 EPS（元） | M27: 摘要統計 | Q27: 🟢 至買進區 | R27: =ROUND(E25*(1-N32),1) -> 304 | S27: =ROUND((E25*(1-N32)-E25)/E25,4) -> -0.0272 | T27: ="再跌 "&TEXT(ABS((E25*(1-N32)-E25)/E25),"0.0%")&" 至 "&TEXT(E25*(1-N32),"0.0")&" 進入積極買進區" -> 再跌 2.7% 至 304.0 進入積極買進區
A28: 季別 | B28: Q1 | C28: Q2 | D28: Q3 | E28: Q4 | G28: 季別 | H28: Q1 | I28: Q2 | J28: Q3 | K28: Q4 | M28: 最高價 | N28: =MAX(C6:C25) -> 345 | Q28: 🔴 至賣出區 | R28: =ROUND(MAX(H25,E25*(1+N32)),1) -> 321 | S28: =ROUND((MAX(H25,E25*(1+N32))-E25)/E25,4) -> 0.0272 | T28: ="再漲 "&TEXT(ABS((MAX(H25,E25*(1+N32))-E25)/E25),"0.0%")&" 至 "&TEXT(MAX(H25,E25*(1+N32)),"0.0")&" 進入反彈賣出區" -> 再漲 2.7% 至 321.0 進入反彈賣出區
A29: 單季 EPS | B29: 5.06 | C29: 4.37 | D29: 4.26 | E29: 5.76 | G29: 單季 EPS | M29: 最低價 | N29: =MIN(D6:D25) -> 284
A30: 全年合計 | B30: 19.45 | G30: 全年合計 | M30: 平均收盤 | N30: =AVERAGE(E6:E25) -> 316.4
A31: 季變化 | B31: — | C31: -0.13636364 | D31: -0.025171625 | E31: 0.35211268 | G31: 季變化 | H31: — | M31: 15日漲幅 | N31: =(E25-E6)/E6 -> 0.075731497
A32: 來源：Yahoo奇摩股市（非官方第三方） | M32: 波動率 | N32: =STDEV(G7:G25)/100 -> 0.027188936
A33: 2382 廣達 ─ 股價合理性評估 | G33: 股價合理性評估（三法平均） | M33: 最新收盤 | N33: =E25 -> 312.5
A34: 股利 | B34: 13 | H34: 便宜價 | I34: 合理價 | J34: 貴價
A35: 每股淨值 | B35: 63.19 | G35: PER 法 | H35: =B36*B30 -> 194.5 | I35: =C36*B30 -> 311.2 | J35: =D36*B30 -> 427.9
A36: PER 倍數 | B36: 10 | C36: 16 | D36: 22 | G36: PBR 法 | H36: =B37*B35 -> 157.975 | I36: =C37*B35 -> 252.76 | J36: =D37*B35 -> 379.14
A37: PBR 倍數 | B37: 2.5 | C37: 4 | D37: 6 | G37: 殖利率法 | H37: =B34/B38 -> 216.66667 | I37: =B34/C38 -> 288.88889 | J37: =B34/D38 -> 433.33333
A38: 殖利率 | B38: 0.06 | C38: 0.045 | D38: 0.03 | G38: 三法平均 | H38: =AVERAGE(H35,H36,H37) -> 189.71389 | I38: =AVERAGE(I35,I36,I37) -> 284.28296 | J38: =AVERAGE(J35,J36,J37) -> 413.45778

Sheet 2395 研華
A1: 2395 研華 - 近20日股價追蹤
A2: 所屬產業： | B2: 工業電腦
A3: 資料來源： | B3: 2395
A5: 日期 | B5: 大盤 | C5: 最高 | D5: 最低 | E5: 收盤 | F5: 成交量(張) | G5: 漲跌幅 | H5: MA5 | I5: MA10 | J5: MA20 | K5: RSI(6) | L5: RSI(12) | M5: KD-K | N5: KD-D | O5: MACD-OSC | Q5: 燈號儀表板
A6: {=INDIRECT("'"&$B$3&"'!"&CHAR(64+COLUMN())&(ROW()-4))} -> 46113 | B6: {=INDIRECT("'"&$B$3&"'!"&CHAR(64+COLUMN())&(ROW()-4))} -> 33174.82 | C6: {=INDIRECT("'"&$B$3&"'!"&CHAR(64+COLUMN())&(ROW()-4))} -> 334 | D6: {=INDIRECT("'"&$B$3&"'!"&CHAR(64+COLUMN())&(ROW()-4))} -> 328 | E6: {=INDIRECT("'"&$B$3&"'!"&CHAR(64+COLUMN())&(ROW()-4))} -> 331 | F6: {=INDIRECT("'"&$B$3&"'!"&CHAR(64+COLUMN())&(ROW()-4))} -> 1943 | G6: {=INDIRECT("'"&$B$3&"'!"&CHAR(64+COLUMN())&(ROW()-4))} -> 3.9246468 | H6: {=INDIRECT("'"&$B$3&"'!"&CHAR(64+COLUMN())&(ROW()-4))} -> 328.5 | ... O6: {=INDIRECT("'"&$B$3&"'!"&CHAR(64+COLUMN())&(ROW()-4))} -> -3.6899713 | Q6: 步驟 | R6: 條件 | S6: 燈號 | T6: 細節
A7: {=INDIRECT("'"&$B$3&"'!"&CHAR(64+COLUMN())&(ROW()-4))} -> 46114 | B7: {=INDIRECT("'"&$B$3&"'!"&CHAR(64+COLUMN())&(ROW()-4))} -> 32572.43 | C7: {=INDIRECT("'"&$B$3&"'!"&CHAR(64+COLUMN())&(ROW()-4))} -> 334 | D7: {=INDIRECT("'"&$B$3&"'!"&CHAR(64+COLUMN())&(ROW()-4))} -> 317 | E7: {=INDIRECT("'"&$B$3&"'!"&CHAR(64+COLUMN())&(ROW()-4))} -> 323.5 | F7: {=INDIRECT("'"&$B$3&"'!"&CHAR(64+COLUMN())&(ROW()-4))} -> 2038 | G7: {=INDIRECT("'"&$B$3&"'!"&CHAR(64+COLUMN())&(ROW()-4))} -> -2.265861 | H7: {=INDIRECT("'"&$B$3&"'!"&CHAR(64+COLUMN())&(ROW()-4))} -> 325.4 | ... O7: {=INDIRECT("'"&$B$3&"'!"&CHAR(64+COLUMN())&(ROW()-4))} -> -3.6249 | Q7: 1 | R7: 大盤過濾（大盤 > 自身 MA20） | S7: =IF(COUNT(B6:B25)<5,"⚪",IF(AND(B25>AVERAGE(B6:B25),B25>B20),"🟢",IF(OR(B25>AVERAGE(B6:B25),B25>B20),"🟡","🔴"))) -> 🟢 | T7: =IF(COUNT(B6:B25)<5,"大盤資料不足","大盤="&TEXT(B25,"#,##0")&" vs MA="&TEXT(AVERAGE(B6:B25),"#,##0")&" 斜率:"&IF(B25>B20,"↑","↓")) -> 大盤=38,927 vs MA=36,644 斜率:↑
A8: {=INDIRECT("'"&$B$3&"'!"&CHAR(64+COLUMN())&(ROW()-4))} -> 46119 | B8: {=INDIRECT("'"&$B$3&"'!"&CHAR(64+COLUMN())&(ROW()-4))} -> 33229.82 | C8: {=INDIRECT("'"&$B$3&"'!"&CHAR(64+COLUMN())&(ROW()-4))} -> 325.5 | D8: {=INDIRECT("'"&$B$3&"'!"&CHAR(64+COLUMN())&(ROW()-4))} -> 318.5 | E8: {=INDIRECT("'"&$B$3&"'!"&CHAR(64+COLUMN())&(ROW()-4))} -> 322.5 | F8: {=INDIRECT("'"&$B$3&"'!"&CHAR(64+COLUMN())&(ROW()-4))} -> 1325 | G8: {=INDIRECT("'"&$B$3&"'!"&CHAR(64+COLUMN())&(ROW()-4))} -> -0.30911901 | H8: {=INDIRECT("'"&$B$3&"'!"&CHAR(64+COLUMN())&(ROW()-4))} -> 323.4 | ... O8: {=INDIRECT("'"&$B$3&"'!"&CHAR(64+COLUMN())&(ROW()-4))} -> -3.503726 | Q8: 2 | R8: 趨勢結構（MA10>MA20 且 MA20 斜率向上） | S8: =IF(OR(I25="",J25="",J20=""),"⚪",IF(AND(I25>J25,J25>J20),"🟢",IF(OR(I25>J25,J25>J20),"🟡","🔴"))) -> 🟢 | T8: =IF(OR(I25="",J25="",J20=""),"資料不足","MA10=" &TEXT(I25,"0.0")& " MA20=" &TEXT(J25,"0.0")& " " &IF(I25>J25,"多頭","空頭")& " 斜率:" &IF(J25>J20,"↑","↓")) -> MA10=362.1 MA20=351.5 多頭 斜率:↑
A9: {=INDIRECT("'"&$B$3&"'!"&CHAR(64+COLUMN())&(ROW()-4))} -> 46120 | B9: {=INDIRECT("'"&$B$3&"'!"&CHAR(64+COLUMN())&(ROW()-4))} -> 34761.38 | C9: {=INDIRECT("'"&$B$3&"'!"&CHAR(64+COLUMN())&(ROW()-4))} -> 351.5 | D9: {=INDIRECT("'"&$B$3&"'!"&CHAR(64+COLUMN())&(ROW()-4))} -> 335 | E9: {=INDIRECT("'"&$B$3&"'!"&CHAR(64+COLUMN())&(ROW()-4))} -> 348.5 | F9: {=INDIRECT("'"&$B$3&"'!"&CHAR(64+COLUMN())&(ROW()-4))} -> 3507 | G9: {=INDIRECT("'"&$B$3&"'!"&CHAR(64+COLUMN())&(ROW()-4))} -> 8.0620155 | H9: {=INDIRECT("'"&$B$3&"'!"&CHAR(64+COLUMN())&(ROW()-4))} -> 328.8 | ... O9: {=INDIRECT("'"&$B$3&"'!"&CHAR(64+COLUMN())&(ROW()-4))} -> -1.6226775 | Q9: 3 | R9: 動能三合（MA5>MA10 + KD金叉 + RSI6>50） | S9: =IF(OR(H25="",I25="",K25="",M25="",N25="",K24="",M24="",N24=""),"⚪",IF(AND(H25>I25,M25>N25,K25>50,OR(AND(M24<N24,M25>N25,M24<50),AND(K24<50,K25>=50),AND(M24<50,M25>=50))),"🟢",IF(AND(H25>I25,M25>N25,K25>50),"🟡",IF(SUM(IF(H25>I25,1,0),IF(M25>N25,1,0),IF(K25>50,1,0))>=2,"🟡","🔴")))) -> 🔴 | T9: ="MA金叉:"&IF(H25>I25,"✓","✗")&" KD金叉:"&IF(AND(M24<N24,M25>N25),"✓","✗")&"(K="&TEXT(M25,"0")&") RSI6:"&TEXT(K25,"0")&IF(AND(K24<50,K25>=50),"(首破50)","") -> MA金叉:✗ KD金叉:✗(K=53) RSI6:51
A10: {=INDIRECT("'"&$B$3&"'!"&CHAR(64+COLUMN())&(ROW()-4))} -> 46121 | B10: {=INDIRECT("'"&$B$3&"'!"&CHAR(64+COLUMN())&(ROW()-4))} -> 34861.16 | C10: {=INDIRECT("'"&$B$3&"'!"&CHAR(64+COLUMN())&(ROW()-4))} -> 353.5 | D10: {=INDIRECT("'"&$B$3&"'!"&CHAR(64+COLUMN())&(ROW()-4))} -> 345 | E10: {=INDIRECT("'"&$B$3&"'!"&CHAR(64+COLUMN())&(ROW()-4))} -> 348 | F10: {=INDIRECT("'"&$B$3&"'!"&CHAR(64+COLUMN())&(ROW()-4))} -> 2795 | G10: {=INDIRECT("'"&$B$3&"'!"&CHAR(64+COLUMN())&(ROW()-4))} -> -0.14347202 | H10: {=INDIRECT("'"&$B$3&"'!"&CHAR(64+COLUMN())&(ROW()-4))} -> 334.7 | ... O10: {=INDIRECT("'"&$B$3&"'!"&CHAR(64+COLUMN())&(ROW()-4))} -> -0.42465104 | Q10: 4 | R10: 量能（≥1.5×5日均量） | S10: =IF(F25="","⚪",IF(S9="🟢",IF(F25>=1.5*AVERAGE(F20:F24),"🟢",IF(F25>=AVERAGE(F20:F24),"🟡","🔴")),IF(S12="🟢",IF(AND(E25>E24,F25<F24),"🔴",IF(F25>=AVERAGE(F20:F24),"🟢","🟡")),IF(F25>=1.5*AVERAGE(F20:F24),"🟢",IF(F25>=AVERAGE(F20:F24),"🟡","🔴"))))) -> 🟡 | T10: ="今量="&TEXT(F25,"#,##0")&" 5日均="&TEXT(AVERAGE(F20:F24),"#,##0")&" 比值="&TEXT(F25/AVERAGE(F20:F24),"0.00")&"x"&IF(AND(E25>E24,F25<F24)," ⚠價漲量縮","") -> 今量=3,072 5日均=2,824 比值=1.09x
A11: {=INDIRECT("'"&$B$3&"'!"&CHAR(64+COLUMN())&(ROW()-4))} -> 46122 | B11: {=INDIRECT("'"&$B$3&"'!"&CHAR(64+COLUMN())&(ROW()-4))} -> 35417.83 | C11: {=INDIRECT("'"&$B$3&"'!"&CHAR(64+COLUMN())&(ROW()-4))} -> 356 | D11: {=INDIRECT("'"&$B$3&"'!"&CHAR(64+COLUMN())&(ROW()-4))} -> 343.5 | E11: {=INDIRECT("'"&$B$3&"'!"&CHAR(64+COLUMN())&(ROW()-4))} -> 346 | F11: {=INDIRECT("'"&$B$3&"'!"&CHAR(64+COLUMN())&(ROW()-4))} -> 2574 | G11: {=INDIRECT("'"&$B$3&"'!"&CHAR(64+COLUMN())&(ROW()-4))} -> -0.57471264 | H11: {=INDIRECT("'"&$B$3&"'!"&CHAR(64+COLUMN())&(ROW()-4))} -> 337.7 | ... O11: {=INDIRECT("'"&$B$3&"'!"&CHAR(64+COLUMN())&(ROW()-4))} -> 0.18770923 | Q11: 5 | R11: 停損參考（三段） | S11: — | T11: ="緊 MA10=" & TEXT(I25,"0.0") & " 中 -" & TEXT(IF(N32<0.025,5,IF(N32<0.04,6,8)),"0") & "%=" & TEXT(E25*(1-IF(N32<0.025,0.05,IF(N32<0.04,0.06,0.08))),"0.0") & " 鬆 MA20=" & TEXT(J25,"0.0") & " (σ=" & TEXT(N32,"0.0%") & ")" -> 緊 MA10=362.1 中 -5%=341.5 鬆 MA20=351.5 (σ=2.3%)
A12: {=INDIRECT("'"&$B$3&"'!"&CHAR(64+COLUMN())&(ROW()-4))} -> 46125 | B12: {=INDIRECT("'"&$B$3&"'!"&CHAR(64+COLUMN())&(ROW()-4))} -> 35457.29 | C12: {=INDIRECT("'"&$B$3&"'!"&CHAR(64+COLUMN())&(ROW()-4))} -> 346.5 | D12: {=INDIRECT("'"&$B$3&"'!"&CHAR(64+COLUMN())&(ROW()-4))} -> 339.5 | E12: {=INDIRECT("'"&$B$3&"'!"&CHAR(64+COLUMN())&(ROW()-4))} -> 342.5 | F12: {=INDIRECT("'"&$B$3&"'!"&CHAR(64+COLUMN())&(ROW()-4))} -> 2053 | G12: {=INDIRECT("'"&$B$3&"'!"&CHAR(64+COLUMN())&(ROW()-4))} -> -1.0115607 | H12: {=INDIRECT("'"&$B$3&"'!"&CHAR(64+COLUMN())&(ROW()-4))} -> 341.5 | ... O12: {=INDIRECT("'"&$B$3&"'!"&CHAR(64+COLUMN())&(ROW()-4))} -> 0.30473005 | Q12: 6 | R12: 持有訊號（收盤>MA5） | S12: =IF(OR(E25="",H25=""),"⚪",IF(E25>H25,"🟢",IF(AND(E25<H25,E24<H24),"🔴","🟡"))) -> 🟡 | T12: ="收盤="&TEXT(E25,"0.0")&" MA5="&TEXT(H25,"0.0")&IF(E25>H25," 守穩",IF(AND(E25<H25,E24<H24)," 連2日跌破"," 單日跌破(警示)")) -> 收盤=359.5 MA5=361.9 單日跌破(警示)
A13: {=INDIRECT("'"&$B$3&"'!"&CHAR(64+COLUMN())&(ROW()-4))} -> 46126 | B13: {=INDIRECT("'"&$B$3&"'!"&CHAR(64+COLUMN())&(ROW()-4))} -> 36296.12 | C13: {=INDIRECT("'"&$B$3&"'!"&CHAR(64+COLUMN())&(ROW()-4))} -> 349.5 | D13: {=INDIRECT("'"&$B$3&"'!"&CHAR(64+COLUMN())&(ROW()-4))} -> 342.5 | E13: {=INDIRECT("'"&$B$3&"'!"&CHAR(64+COLUMN())&(ROW()-4))} -> 344 | F13: {=INDIRECT("'"&$B$3&"'!"&CHAR(64+COLUMN())&(ROW()-4))} -> 2414 | G13: {=INDIRECT("'"&$B$3&"'!"&CHAR(64+COLUMN())&(ROW()-4))} -> 0.4379562 | H13: {=INDIRECT("'"&$B$3&"'!"&CHAR(64+COLUMN())&(ROW()-4))} -> 345.8 | ... O13: {=INDIRECT("'"&$B$3&"'!"&CHAR(64+COLUMN())&(ROW()-4))} -> 0.42354103 | Q13: 7 | R13: 出場警示（4取2） | S13: =IF(SUM(IF(AND(E25>MAX(E15:E24),K25<MAX(K15:K24)),1,0),IF(AND(E25>MAX(E15:E24),F25<MAX(F15:F24)),1,0),IF(AND(E25<H25,H25<H24),1,0),IF(AND(M24>N24,M25<N25,M24>80),1,0),IF(AND(E25<J25,E24<J24),1,0))>=2,"🔴",IF(SUM(IF(AND(E25>MAX(E15:E24),K25<MAX(K15:K24)),1,0),IF(AND(E25>MAX(E15:E24),F25<MAX(F15:F24)),1,0),IF(AND(E25<H25,H25<H24),1,0),IF(AND(M24>N24,M25<N25,M24>80),1,0),IF(AND(E25<J25,E24<J24),1,0))=1,"🟡","🟢")) -> 🟢 | T13: ="RSI背離:"&IF(AND(E25>MAX(E15:E24),K25<MAX(K15:K24)),"✓","✗")&" 量價背離:"&IF(AND(E25>MAX(E15:E24),F25<MAX(F15:F24)),"✓","✗")&" MA5翻下:"&IF(AND(E25<H25,H25<H24),"✓","✗")&" KD高死叉:"&IF(AND(M24>N24,M25<N25,M24>80),"✓","✗")&" 破MA20:"&IF(AND(E25<J25,E24<J24),"✓","✗") -> RSI背離:✗ 量價背離:✗ MA5翻下:✗ KD高死叉:✗ 破MA20:✗
A14: {=INDIRECT("'"&$B$3&"'!"&CHAR(64+COLUMN())&(ROW()-4))} -> 46127 | B14: {=INDIRECT("'"&$B$3&"'!"&CHAR(64+COLUMN())&(ROW()-4))} -> 36722.14 | C14: {=INDIRECT("'"&$B$3&"'!"&CHAR(64+COLUMN())&(ROW()-4))} -> 351.5 | D14: {=INDIRECT("'"&$B$3&"'!"&CHAR(64+COLUMN())&(ROW()-4))} -> 345.5 | E14: {=INDIRECT("'"&$B$3&"'!"&CHAR(64+COLUMN())&(ROW()-4))} -> 348 | F14: {=INDIRECT("'"&$B$3&"'!"&CHAR(64+COLUMN())&(ROW()-4))} -> 2818 | G14: {=INDIRECT("'"&$B$3&"'!"&CHAR(64+COLUMN())&(ROW()-4))} -> 1.1627907 | H14: {=INDIRECT("'"&$B$3&"'!"&CHAR(64+COLUMN())&(ROW()-4))} -> 345.7 | ... O14: {=INDIRECT("'"&$B$3&"'!"&CHAR(64+COLUMN())&(ROW()-4))} -> 0.69582461
A15: {=INDIRECT("'"&$B$3&"'!"&CHAR(64+COLUMN())&(ROW()-4))} -> 46128 | B15: {=INDIRECT("'"&$B$3&"'!"&CHAR(64+COLUMN())&(ROW()-4))} -> 37132.02 | C15: {=INDIRECT("'"&$B$3&"'!"&CHAR(64+COLUMN())&(ROW()-4))} -> 362 | D15: {=INDIRECT("'"&$B$3&"'!"&CHAR(64+COLUMN())&(ROW()-4))} -> 351.5 | E15: {=INDIRECT("'"&$B$3&"'!"&CHAR(64+COLUMN())&(ROW()-4))} -> 355 | F15: {=INDIRECT("'"&$B$3&"'!"&CHAR(64+COLUMN())&(ROW()-4))} -> 3946 | G15: {=INDIRECT("'"&$B$3&"'!"&CHAR(64+COLUMN())&(ROW()-4))} -> 2.0114943 | H15: {=INDIRECT("'"&$B$3&"'!"&CHAR(64+COLUMN())&(ROW()-4))} -> 347.1 | ... O15: {=INDIRECT("'"&$B$3&"'!"&CHAR(64+COLUMN())&(ROW()-4))} -> 1.2398954 | Q15: 總燈號 | R15: ="通過 "&(COUNTIF(S7:S13,"🟢"))&" / 7 警示 "&COUNTIF(S7:S13,"🟡")&" 危險 "&COUNTIF(S7:S13,"🔴") -> 通過 3 / 7 警示 2 危險 1 | S15: =IF(AND(S7="🟢",COUNTIF(S7:S10,"🟢")=4,S13<>"🔴"),"🟢 強進場",IF(AND(S7="🟢",COUNTIF(S7:S10,"🟢")>=3,S13<>"🔴"),"🟢 次強進場",IF(S13="🔴","🔴 出場",IF(COUNTIF(S7:S13,"🔴")>=2,"🔴 觀望","🟡 等待")))) -> 🟡 等待 | T15: ="基於 "&TEXT(A25,"yyyy/mm/dd")&" 收盤資料" -> 基於 2026/04/30 收盤資料
A16: {=INDIRECT("'"&$B$3&"'!"&CHAR(64+COLUMN())&(ROW()-4))} -> 46129 | B16: {=INDIRECT("'"&$B$3&"'!"&CHAR(64+COLUMN())&(ROW()-4))} -> 36804.34 | C16: {=INDIRECT("'"&$B$3&"'!"&CHAR(64+COLUMN())&(ROW()-4))} -> 372 | D16: {=INDIRECT("'"&$B$3&"'!"&CHAR(64+COLUMN())&(ROW()-4))} -> 359.5 | E16: {=INDIRECT("'"&$B$3&"'!"&CHAR(64+COLUMN())&(ROW()-4))} -> 366 | F16: {=INDIRECT("'"&$B$3&"'!"&CHAR(64+COLUMN())&(ROW()-4))} -> 5334 | G16: {=INDIRECT("'"&$B$3&"'!"&CHAR(64+COLUMN())&(ROW()-4))} -> 3.0985915 | H16: {=INDIRECT("'"&$B$3&"'!"&CHAR(64+COLUMN())&(ROW()-4))} -> 351.1 | ... O16: {=INDIRECT("'"&$B$3&"'!"&CHAR(64+COLUMN())&(ROW()-4))} -> 2.1782406
A17: {=INDIRECT("'"&$B$3&"'!"&CHAR(64+COLUMN())&(ROW()-4))} -> 46132 | B17: {=INDIRECT("'"&$B$3&"'!"&CHAR(64+COLUMN())&(ROW()-4))} -> 36958.8 | C17: {=INDIRECT("'"&$B$3&"'!"&CHAR(64+COLUMN())&(ROW()-4))} -> 376.5 | D17: {=INDIRECT("'"&$B$3&"'!"&CHAR(64+COLUMN())&(ROW()-4))} -> 363 | E17: {=INDIRECT("'"&$B$3&"'!"&CHAR(64+COLUMN())&(ROW()-4))} -> 363.5 | F17: {=INDIRECT("'"&$B$3&"'!"&CHAR(64+COLUMN())&(ROW()-4))} -> 3362 | G17: {=INDIRECT("'"&$B$3&"'!"&CHAR(64+COLUMN())&(ROW()-4))} -> -0.68306011 | H17: {=INDIRECT("'"&$B$3&"'!"&CHAR(64+COLUMN())&(ROW()-4))} -> 355.3 | ... O17: {=INDIRECT("'"&$B$3&"'!"&CHAR(64+COLUMN())&(ROW()-4))} -> 2.4480168 | Q17: 隔日參考價位
A18: {=INDIRECT("'"&$B$3&"'!"&CHAR(64+COLUMN())&(ROW()-4))} -> 46133 | B18: {=INDIRECT("'"&$B$3&"'!"&CHAR(64+COLUMN())&(ROW()-4))} -> 37605.11 | C18: {=INDIRECT("'"&$B$3&"'!"&CHAR(64+COLUMN())&(ROW()-4))} -> 368 | D18: {=INDIRECT("'"&$B$3&"'!"&CHAR(64+COLUMN())&(ROW()-4))} -> 355.5 | E18: {=INDIRECT("'"&$B$3&"'!"&CHAR(64+COLUMN())&(ROW()-4))} -> 364.5 | F18: {=INDIRECT("'"&$B$3&"'!"&CHAR(64+COLUMN())&(ROW()-4))} -> 2497 | G18: {=INDIRECT("'"&$B$3&"'!"&CHAR(64+COLUMN())&(ROW()-4))} -> 0.27510316 | H18: {=INDIRECT("'"&$B$3&"'!"&CHAR(64+COLUMN())&(ROW()-4))} -> 359.4 | ... O18: {=INDIRECT("'"&$B$3&"'!"&CHAR(64+COLUMN())&(ROW()-4))} -> 2.502387 | Q18: 區間 | R18: 技術依據 | S18: 下緣 | T18: 上緣
A19: {=INDIRECT("'"&$B$3&"'!"&CHAR(64+COLUMN())&(ROW()-4))} -> 46134 | B19: {=INDIRECT("'"&$B$3&"'!"&CHAR(64+COLUMN())&(ROW()-4))} -> 37878.47 | C19: {=INDIRECT("'"&$B$3&"'!"&CHAR(64+COLUMN())&(ROW()-4))} -> 366 | D19: {=INDIRECT("'"&$B$3&"'!"&CHAR(64+COLUMN())&(ROW()-4))} -> 361 | E19: {=INDIRECT("'"&$B$3&"'!"&CHAR(64+COLUMN())&(ROW()-4))} -> 361 | F19: {=INDIRECT("'"&$B$3&"'!"&CHAR(64+COLUMN())&(ROW()-4))} -> 2504 | G19: {=INDIRECT("'"&$B$3&"'!"&CHAR(64+COLUMN())&(ROW()-4))} -> -0.96021948 | H19: {=INDIRECT("'"&$B$3&"'!"&CHAR(64+COLUMN())&(ROW()-4))} -> 362 | ... O19: {=INDIRECT("'"&$B$3&"'!"&CHAR(64+COLUMN())&(ROW()-4))} -> 2.1260118 | Q19: 🟢 積極買進 | R19: -1σ 統計下緣 | S19: =IF(LEFT($S$15,1)="🟢",ROUND(E25*(1-N32*1.2),1),"—") -> — | T19: =IF(LEFT($S$15,1)="🟢",ROUND(E25*(1-N32*0.8),1),"—") -> —
A20: {=INDIRECT("'"&$B$3&"'!"&CHAR(64+COLUMN())&(ROW()-4))} -> 46135 | B20: {=INDIRECT("'"&$B$3&"'!"&CHAR(64+COLUMN())&(ROW()-4))} -> 37714.15 | C20: {=INDIRECT("'"&$B$3&"'!"&CHAR(64+COLUMN())&(ROW()-4))} -> 370 | D20: {=INDIRECT("'"&$B$3&"'!"&CHAR(64+COLUMN())&(ROW()-4))} -> 348 | E20: {=INDIRECT("'"&$B$3&"'!"&CHAR(64+COLUMN())&(ROW()-4))} -> 356.5 | F20: {=INDIRECT("'"&$B$3&"'!"&CHAR(64+COLUMN())&(ROW()-4))} -> 2674 | G20: {=INDIRECT("'"&$B$3&"'!"&CHAR(64+COLUMN())&(ROW()-4))} -> -1.2465374 | H20: {=INDIRECT("'"&$B$3&"'!"&CHAR(64+COLUMN())&(ROW()-4))} -> 362.3 | ... O20: {=INDIRECT("'"&$B$3&"'!"&CHAR(64+COLUMN())&(ROW()-4))} -> 1.4307207 | Q20: 🟡 較安全買點 | R20: -1.5σ 跌深區 | S20: =IF(LEFT($S$15,1)="🟢",ROUND(E25*(1-N32*1.8),1),"—") -> — | T20: =IF(LEFT($S$15,1)="🟢",ROUND(E25*(1-N32*1.4),1),"—") -> —
A21: {=INDIRECT("'"&$B$3&"'!"&CHAR(64+COLUMN())&(ROW()-4))} -> 46136 | B21: {=INDIRECT("'"&$B$3&"'!"&CHAR(64+COLUMN())&(ROW()-4))} -> 38932.4 | C21: {=INDIRECT("'"&$B$3&"'!"&CHAR(64+COLUMN())&(ROW()-4))} -> 358 | D21: {=INDIRECT("'"&$B$3&"'!"&CHAR(64+COLUMN())&(ROW()-4))} -> 349 | E21: {=INDIRECT("'"&$B$3&"'!"&CHAR(64+COLUMN())&(ROW()-4))} -> 354 | F21: {=INDIRECT("'"&$B$3&"'!"&CHAR(64+COLUMN())&(ROW()-4))} -> 1858 | G21: {=INDIRECT("'"&$B$3&"'!"&CHAR(64+COLUMN())&(ROW()-4))} -> -0.70126227 | H21: {=INDIRECT("'"&$B$3&"'!"&CHAR(64+COLUMN())&(ROW()-4))} -> 359.9 | ... O21: {=INDIRECT("'"&$B$3&"'!"&CHAR(64+COLUMN())&(ROW()-4))} -> 0.69636202 | Q21: 🔵 強支撐買點 | R21: -2σ 強支撐 | S21: =IF(LEFT($S$15,1)="🟢",ROUND(E25*(1-N32*2.4),1),"—") -> — | T21: =IF(LEFT($S$15,1)="🟢",ROUND(E25*(1-N32*2),1),"—") -> —
